Workbook

Sheet SCHEDULE
A1: FIFA 2026 SCHEDULE
A2: Enter WINNER after each match. POINTS table auto-calculates. Green = Dallas.
A4: Match | B4: Stage | C4: Date | D4: Team 1 | E4: Team 2 | F4: Venue | G4: WINNER
A5: M1 | B5: Group A | C5: Jun 11 | D5: Mexico | E5: South Africa | F5: Estadio Azteca, Mexico City
A6: M2 | B6: Group A | C6: Jun 11 | D6: South Korea | E6: UEFA D | F6: Estadio Akron, Zap
A7: M3 | B7: Group B | C7: Jun 12 | D7: Canada | E7: UEFA A | F7: BMO Field, Toronto
A8: M4 | B8: Group D | C8: Jun 12 | D8: United States | E8: Paraguay | F8: SoFi Stadium, Inglewood
A9: M8 | B9: Group B | C9: Jun 13 | D9: Qatar | E9: Switzerland | F9: Levi's Stadium, Santa Clara
A10: M7 | B10: Group C | C10: Jun 13 | D10: Brazil | E10: Morocco | F10: MetLife Stadium, East Rutherford
A11: M5 | B11: Group C | C11: Jun 13 | D11: Haiti | E11: Scotland | F11: Gillette Stadium, Foxborough
A12: M6 | B12: Group D | C12: Jun 13 | D12: Australia | E12: UEFA C | F12: BC Place, Vancouver
A13: M10 | B13: Group E | C13: Jun 14 | D13: Germany | E13: Curacao | F13: NRG Stadium, Houston
A14: M11 | B14: Group F | C14: Jun 14 | D14: Netherlands | E14: Japan | F14: AT&T Stadium, Arlington
A15: M9 | B15: Group E | C15: Jun 14 | D15: Ivory Coast | E15: Ecuador | F15: Lincoln Financial Field, Philadelphia
A16: M12 | B16: Group F | C16: Jun 14 | D16: UEFA B | E16: Tunisia | F16: Estadio BBVA, Guadalupe
... A108: M104 | B108: Final | C108: Jul 19 | D108: W191 | E108: W102 | F108: MetLife Stadium, East Rutherford

Sheet DALLAS GAMES
B2: DALLAS COPART CLIENT ENTERTAINMENT - PROBABILITY ANALYSIS
B4: Note - Dynamically showing what 2E could be with probability/chance -- NEXT STEPS
B6: RECOMMENDED CLIENT INVITE STRATEGY
B7: Priority | C7: Date | D7: Match | E7: Teams | F7: Clients | G7: Notes
B8: P0 - BOOK NOW | C8: Jun 14 | D8: M11 (Group F) | E8: Netherlands vs Japan
B9: P0 - BOOK NOW | C9: Jun 17 | D9: M21 (Group L) | E9: England vs Croatia | G9: Premium European matchup (2018 semifinals)
B10: P0 - BOOK NOW | C10: Jun 22 | D10: M43 (Group J) | E10: Argentina vs Austria | G10: Defending champs
B11: P0 - BOOK NOW | C11: Jun 27 | D11: M70 (Group J) | E11: Argentina vs Jordan
B12: P1 - MONITOR | C12: Jun 30 | D12: M78 (R32) | E12: 2E vs 2I | G12: Germany/France possible
B13: P1 - MONITOR | C13: Jul 3 | D13: M88 (R32) | E13: 2D vs 2G | G13: USA/Belgium possible
B14: P2 - TENTATIVE | C14: Jul 6 | D14: M93 (R16) | E14: W83 vs W84 | G14: Top teams
B15: P0 - BOOK NOW | C15: Jul 14 | D15: M101 (SF) | E15: W97 vs W98 | G15: SEMIFINAL - Premium

Sheet DASHBOARD
A1: DALLAS MATCH PREDICTIONS
A2: Multi-layer market data | Corrected P(2nd) with 67% 3rd-place factor | Dynamic updates
A4: M78 - Jun 30 [DALLAS R32]: 2E vs 2I
A5: # | B5: Team 1 | C5: P% | D5: Team 2 | E5: P% | F5: Combined
A6: 1 | B6: ='M78'!B35 -> Ecuador | C6: ='M78'!C35 -> 0.35314349 | D6: ='M78'!D35 -> Norway | E6: ='M78'!E35 -> 0.31197984 | F6: ='M78'!F35 -> 0.11017365
A7: 2 | B7: ='M78'!B36 -> Ecuador | C7: ='M78'!C36 -> 0.35314349 | D7: ='M78'!D36 -> France | E7: ='M78'!E36 -> 0.23272701 | F7: ='M78'!F36 -> 0.082186029
A8: 3 | B8: ='M78'!B37 -> Germany | C8: ='M78'!C37 -> 0.25066507 | D8: ='M78'!D37 -> Norway | E8: ='M78'!E37 -> 0.31197984 | F8: ='M78'!F37 -> 0.078202447
A10: M83 - Jul 4 [Toronto]: 2K vs 2L → feeds M93
A11: # | B11: Team 1 | C11: P% | D11: Team 2 | E11: P% | F11: Combined
A12: 1 | B12: ='M83'!B35 -> Colombia | C12: ='M83'!C35 -> 0.36151026 | D12: ='M83'!D35 -> Croatia | E12: ='M83'!E35 -> 0.25622664 | F12: ='M83'!F35 -> 0.092628558
A13: 2 | B13: ='M83'!B36 -> Colombia | C13: ='M83'!C36 -> 0.36151026 | D13: ='M83'!D36 -> England | E13: ='M83'!E36 -> 0.23809781 | F13: ='M83'!F36 -> 0.086074799
A14: 3 | B14: ='M83'!B37 -> Portugal | C14: ='M83'!C37 -> 0.22530289 | D14: ='M83'!D37 -> Croatia | E14: ='M83'!E37 -> 0.25622664 | F14: ='M83'!F37 -> 0.057728601
A16: M84 - Jul 4 [LA]: 1H vs 2J → feeds M93
A17: # | B17: Team 1 | C17: P% | D17: Team 2 | E17: P% | F17: Combined
A18: 1 | B18: ='M84'!B35 -> Spain | C18: ='M84'!C35 -> 0.7745098 | D18: ='M84'!D35 -> Austria | E18: ='M84'!E35 -> 0.27000582 | F18: ='M84'!F35 -> 0.20912215
A19: 2 | B19: ='M84'!B36 -> Spain | C19: ='M84'!C36 -> 0.7745098 | D19: ='M84'!D36 -> Argentina | E19: ='M84'!E36 -> 0.25600729 | F19: ='M84'!F36 -> 0.19828016
A20: 3 | B20: ='M84'!B37 -> Spain | C20: ='M84'!C37 -> 0.7745098 | D20: ='M84'!D37 -> Algeria | E20: ='M84'!E37 -> 0.18031345 | F20: ='M84'!F37 -> 0.13965453
A22: M88 - Jul 3 [DALLAS R32]: 2D vs 2G
A23: # | B23: Team 1 | C23: P% | D23: Team 2 | E23: P% | F23: Combined
A24: 1 | B24: ='M88'!B35 -> United States | C24: ='M88'!C35 -> 0.29833886 | D24: ='M88'!D35 -> Belgium | E24: ='M88'!E35 -> 0.23881651 | F24: ='M88'!F35 -> 0.071248247
A25: 2 | B25: ='M88'!B36 -> United States | C25: ='M88'!C36 -> 0.29833886 | D25: ='M88'!D36 -> Egypt | E25: ='M88'!E36 -> 0.19859442 | F25: ='M88'!F36 -> 0.059248434
A26: 3 | B26: ='M88'!B37 -> Paraguay | C26: ='M88'!C37 -> 0.22298972 | D26: ='M88'!D37 -> Belgium | E26: ='M88'!E37 -> 0.23881651 | F26: ='M88'!F37 -> 0.053253628
A28: M93 - Jul 6 [DALLAS R16]: W83 vs W84
A29: # | B29: Team 1 | C29: P% | D29: Team 2 | E29: P% | F29: Combined
A30: 1 | B30: ='M93'!B87 -> Colombia | C30: ='M93'!C87 -> 0.19883064 | D30: ='M93'!D87 -> Spain | E30: ='M93'!E87 -> 0.34852941 | F30: ='M93'!F87 -> 0.069298327
A31: 2 | B31: ='M93'!B88 -> Croatia | C31: ='M93'!C88 -> 0.14092465 | D31: ='M93'!D88 -> Spain | E31: ='M93'!E88 -> 0.34852941 | F31: ='M93'!F88 -> 0.049116386
A32: 3 | B32: ='M93'!B89 -> England | C32: ='M93'!C89 -> 0.13095379 | D32: ='M93'!D89 -> Spain | E32: ='M93'!E89 -> 0.34852941 | F32: ='M93'!F89 -> 0.045641248
A34: M101 - Jul 14 [DALLAS SF]: Using Final Qualifier Odds
A35: # | B35: Team 1 | C35: P% | D35: Team 2 | E35: P% | F35: Combined
A36: 1 | B36: ='M101'!B19 -> Argentina | C36: ='M101'!C19 -> 0.208 | D36: ='M101'!D19 -> Spain | E36: ='M101'!E19 -> 0.318 | F36: ='M101'!F19 -> 0.066144
A37: 2 | B37: ='M101'!B20 -> Argentina | C37: ='M101'!C20 -> 0.208 | D37: ='M101'!D20 -> England | E37: ='M101'!E20 -> 0.26 | F37: ='M101'!F20 -> 0.05408
A38: 3 | B38: ='M101'!B21 -> Spain | C38: ='M101'!C21 -> 0.318 | D38: ='M101'!D21 -> England | E38: ='M101'!E21 -> 0.26 | F38: ='M101'!F21 -> 0.08268
A41: KEY FORMULAS
A42: P(2nd) = α × (Q - W) / (0.67 + 0.33α) where α = W/(W + avg_others)
A43: Q = W + P(2nd) + 0.67×P(3rd) → Accounts for 8/12 = 67% of 3rd place teams qualifying
A44: P(Reach SF) = 2 × P(Final) → Assumes P(Win SF) ≈ 50%
A46: HOW TO UPDATE
A47: 1. ODDS: Update yellow cells with latest Polymarket/Kalshi odds
A48: 2. SCHEDULE: Enter WINNER after each match → POINTS auto-calculates
A49: 3. Match sheets: Once M83/M84 complete, enter winner in B3 → M93 updates to 100%/0%
...

Sheet ODDS
A1: PREDICTION MARKET ODDS
A2: Yellow cells = inputs from Polymarket/Kalshi
A4: GROUP WINNER ODDS (P(1st))
A5: Group | B5: Team | C5: Yes Prices | D5: Win %
A6: D | B6: United States | C6: 47 | D6: =C6/SUM($C$6:$C$9)*100 -> 43.518519
A7: D | B7: Paraguay | C7: 23 | D7: =C7/SUM($C$6:$C$9)*100 -> 21.296296
A8: D | B8: Australia | C8: 15 | D8: =C8/SUM($C$6:$C$9)*100 -> 13.888889
A9: D | B9: TBD_C | C9: 23 | D9: =C9/SUM($C$6:$C$9)*100 -> 21.296296
A11: E | B11: Germany | C11: 66 | D11: =C11/SUM($C$11:$C$14)*100 -> 69.473684
A12: E | B12: Ecuador | C12: 18 | D12: =C12/SUM($C$11:$C$14)*100 -> 18.947368
A13: E | B13: Ivory Coast | C13: 10 | D13: =C13/SUM($C$11:$C$14)*100 -> 10.526316
A14: E | B14: Curacao | C14: 1 | D14: =C14/SUM($C$11:$C$14)*100 -> 1.0526316
A16: G | B16: Belgium | C16: 68 | D16: =C16/SUM($C$16:$C$19)*100 -> 68.686869
A17: G | B17: Egypt | C17: 18 | D17: =C17/SUM($C$16:$C$19)*100 -> 18.181818
A18: G | B18: Iran | C18: 8 | D18: =C18/SUM($C$16:$C$19)*100 -> 8.0808081
A19: G | B19: New Zealand | C19: 5 | D19: =C19/SUM($C$16:$C$19)*100 -> 5.0505051
A21: H | B21: Spain | C21: 79 | D21: =C21/SUM($C$21:$C$24)*100 -> 77.45098
A22: H | B22: Uruguay | C22: 15 | D22: =C22/SUM($C$21:$C$24)*100 -> 14.705882
A23: H | B23: Saudi Arabia | C23: 4 | D23: =C23/SUM($C$21:$C$24)*100 -> 3.9215686
A24: H | B24: Cape Verde | C24: 4 | D24: =C24/SUM($C$21:$C$24)*100 -> 3.9215686
A26: I | B26: France | C26: 69 | D26: =C26/SUM($C$26:$C$29)*100 -> 68.316832
A27: I | B27: Senegal | C27: 9 | D27: =C27/SUM($C$26:$C$29)*100 -> 8.9108911
A28: I | B28: Norway | C28: 22 | D28: =C28/SUM($C$26:$C$29)*100 -> 21.782178
A29: I | B29: TBD_I4 | C29: 1 | D29: =C29/SUM($C$26:$C$29)*100 -> 0.99009901
A31: J | B31: Argentina | C31: 75 | D31: =C31/SUM($C$31:$C$34)*100 -> 68.807339
A32: J | B32: Austria | C32: 18 | D32: =C32/SUM($C$31:$C$34)*100 -> 16.513761
A33: J | B33: Jordan | C33: 5 | D33: =C33/SUM($C$31:$C$34)*100 -> 4.587156
A34: J | B34: Algeria | C34: 11 | D34: =C34/SUM($C$31:$C$34)*100 -> 10.091743
A36: K | B36: Portugal | C36: 69 | D36: =C36/SUM($C$36:$C$39)*100 -> 66.990291
A37: K | B37: Colombia | C37: 31 | D37: =C37/SUM($C$36:$C$39)*100 -> 30.097087
A38: K | B38: Uzbekistan | C38: 2 | D38: =C38/SUM($C$36:$C$39)*100 -> 1.9417476
A39: K | B39: TBD_K4 | C39: 1 | D39: =C39/SUM($C$36:$C$39)*100 -> 0.97087379
A41: L | B41: England | C41: 69 | D41: =C41/SUM($C$41:$C$44)*100 -> 67.647059
A42: L | B42: Croatia | C42: 22 | D42: =C42/SUM($C$41:$C$44)*100 -> 21.568627
A43: L | B43: Ghana | C43: 10 | D43: =C43/SUM($C$41:$C$44)*100 -> 9.8039216
A44: L | B44: Panama | C44: 1 | D44: =C44/SUM($C$41:$C$44)*100 -> 0.98039216
A47: GROUP QUALIFIER ODDS (P(1st or 2nd or 3rd-qualified - if in top 8))
A48: Group | B48: Team | C48: Qualify %
A49: D | B49: United States | C49: 82
A50: D | B50: Paraguay | C50: 62
...

Sheet POINTS
A1: GROUP STANDINGS (Auto-calculated from SCHEDULE)
A2: W=3pts, D=1pt, L=0 pts. Position = RANK by points.
A4: GROUP D
A5: Team | B5: Played | C5: W | D5: D | E5: L | F5: GD | G5: Pts | H5: Pos | I5: Confirmed | K5: NEXT STEPS - Using GD
A6: United States | B6: =COUNTIFS(SCHEDULE!$B:$B,"Group D",SCHEDULE!$D:$D,A6,SCHEDULE!$G:$G,"<>")+COUNTIFS(SCHEDULE!$B:$B,"Group D",SCHEDULE!$F:$F,A6,SCHEDULE!$G:$G,"<>") -> 0 | C6: =COUNTIFS(SCHEDULE!$B:$B,"Group D",SCHEDULE!$D:$D,A6,SCHEDULE!$G:$G,A6)+COUNTIFS(SCHEDULE!$B:$B,"Group D",SCHEDULE!$F:$F,A6,SCHEDULE!$G:$G,A6) -> 0 | D6: =COUNTIFS(SCHEDULE!$B:$B,"Group D",SCHEDULE!$D:$D,A6,SCHEDULE!$G:$G,"Draw")+COUNTIFS(SCHEDULE!$B:$B,"Group D",SCHEDULE!$F:$F,A6,SCHEDULE!$G:$G,"Draw") -> 0 | E6: =B6-C6-D6 -> 0 | F6: 0 | G6: =C6*3+D6 -> 0 | H6: =IF(B6=0,"?",RANK(G6,$G$6:$G$9,0)) -> ? | I6: =IF(B6=3,H6,"")
A7: Paraguay | B7: =COUNTIFS(SCHEDULE!$B:$B,"Group D",SCHEDULE!$D:$D,A7,SCHEDULE!$G:$G,"<>")+COUNTIFS(SCHEDULE!$B:$B,"Group D",SCHEDULE!$F:$F,A7,SCHEDULE!$G:$G,"<>") -> 0 | C7: =COUNTIFS(SCHEDULE!$B:$B,"Group D",SCHEDULE!$D:$D,A7,SCHEDULE!$G:$G,A7)+COUNTIFS(SCHEDULE!$B:$B,"Group D",SCHEDULE!$F:$F,A7,SCHEDULE!$G:$G,A7) -> 0 | D7: =COUNTIFS(SCHEDULE!$B:$B,"Group D",SCHEDULE!$D:$D,A7,SCHEDULE!$G:$G,"Draw")+COUNTIFS(SCHEDULE!$B:$B,"Group D",SCHEDULE!$F:$F,A7,SCHEDULE!$G:$G,"Draw") -> 0 | E7: =B7-C7-D7 -> 0 | F7: 0 | G7: =C7*3+D7 -> 0 | H7: =IF(B7=0,"?",RANK(G7,$G$6:$G$9,0)) -> ? | I7: =IF(B7=3,H7,"")
A8: Australia | B8: =COUNTIFS(SCHEDULE!$B:$B,"Group D",SCHEDULE!$D:$D,A8,SCHEDULE!$G:$G,"<>")+COUNTIFS(SCHEDULE!$B:$B,"Group D",SCHEDULE!$F:$F,A8,SCHEDULE!$G:$G,"<>") -> 0 | C8: =COUNTIFS(SCHEDULE!$B:$B,"Group D",SCHEDULE!$D:$D,A8,SCHEDULE!$G:$G,A8)+COUNTIFS(SCHEDULE!$B:$B,"Group D",SCHEDULE!$F:$F,A8,SCHEDULE!$G:$G,A8) -> 0 | D8: =COUNTIFS(SCHEDULE!$B:$B,"Group D",SCHEDULE!$D:$D,A8,SCHEDULE!$G:$G,"Draw")+COUNTIFS(SCHEDULE!$B:$B,"Group D",SCHEDULE!$F:$F,A8,SCHEDULE!$G:$G,"Draw") -> 0 | E8: =B8-C8-D8 -> 0 | F8: 0 | G8: =C8*3+D8 -> 0 | H8: =IF(B8=0,"?",RANK(G8,$G$6:$G$9,0)) -> ? | I8: =IF(B8=3,H8,"")
A9: TBD_C | B9: =COUNTIFS(SCHEDULE!$B:$B,"Group D",SCHEDULE!$D:$D,A9,SCHEDULE!$G:$G,"<>")+COUNTIFS(SCHEDULE!$B:$B,"Group D",SCHEDULE!$F:$F,A9,SCHEDULE!$G:$G,"<>") -> 0 | C9: =COUNTIFS(SCHEDULE!$B:$B,"Group D",SCHEDULE!$D:$D,A9,SCHEDULE!$G:$G,A9)+COUNTIFS(SCHEDULE!$B:$B,"Group D",SCHEDULE!$F:$F,A9,SCHEDULE!$G:$G,A9) -> 0 | D9: =COUNTIFS(SCHEDULE!$B:$B,"Group D",SCHEDULE!$D:$D,A9,SCHEDULE!$G:$G,"Draw")+COUNTIFS(SCHEDULE!$B:$B,"Group D",SCHEDULE!$F:$F,A9,SCHEDULE!$G:$G,"Draw") -> 0 | E9: =B9-C9-D9 -> 0 | F9: 0 | G9: =C9*3+D9 -> 0 | H9: =IF(B9=0,"?",RANK(G9,$G$6:$G$9,0)) -> ? | I9: =IF(B9=3,H9,"")
A11: GROUP E
A12: Team | B12: Played | C12: W | D12: D | E12: L | F12: GD | G12: Pts | H12: Pos | I12: Confirmed
A13: Germany | B13: =COUNTIFS(SCHEDULE!$B:$B,"Group E",SCHEDULE!$D:$D,A13,SCHEDULE!$G:$G,"<>")+COUNTIFS(SCHEDULE!$B:$B,"Group E",SCHEDULE!$F:$F,A13,SCHEDULE!$G:$G,"<>") -> 0 | C13: =COUNTIFS(SCHEDULE!$B:$B,"Group E",SCHEDULE!$D:$D,A13,SCHEDULE!$G:$G,A13)+COUNTIFS(SCHEDULE!$B:$B,"Group E",SCHEDULE!$F:$F,A13,SCHEDULE!$G:$G,A13) -> 0 | D13: =COUNTIFS(SCHEDULE!$B:$B,"Group E",SCHEDULE!$D:$D,A13,SCHEDULE!$G:$G,"Draw")+COUNTIFS(SCHEDULE!$B:$B,"Group E",SCHEDULE!$F:$F,A13,SCHEDULE!$G:$G,"Draw") -> 0 | E13: =B13-C13-D13 -> 0 | F13: 0 | G13: =C13*3+D13 -> 0 | H13: =IF(B13=0,"?",RANK(G13,$G$13:$G$16,0)) -> ? | I13: =IF(B13=3,H13,"")
A14: Ecuador | B14: =COUNTIFS(SCHEDULE!$B:$B,"Group E",SCHEDULE!$D:$D,A14,SCHEDULE!$G:$G,"<>")+COUNTIFS(SCHEDULE!$B:$B,"Group E",SCHEDULE!$F:$F,A14,SCHEDULE!$G:$G,"<>") -> 0 | C14: =COUNTIFS(SCHEDULE!$B:$B,"Group E",SCHEDULE!$D:$D,A14,SCHEDULE!$G:$G,A14)+COUNTIFS(SCHEDULE!$B:$B,"Group E",SCHEDULE!$F:$F,A14,SCHEDULE!$G:$G,A14) -> 0 | D14: =COUNTIFS(SCHEDULE!$B:$B,"Group E",SCHEDULE!$D:$D,A14,SCHEDULE!$G:$G,"Draw")+COUNTIFS(SCHEDULE!$B:$B,"Group E",SCHEDULE!$F:$F,A14,SCHEDULE!$G:$G,"Draw") -> 0 | E14: =B14-C14-D14 -> 0 | F14: 0 | G14: =C14*3+D14 -> 0 | H14: =IF(B14=0,"?",RANK(G14,$G$13:$G$16,0)) -> ? | I14: =IF(B14=3,H14,"")
A15: Ivory Coast | B15: =COUNTIFS(SCHEDULE!$B:$B,"Group E",SCHEDULE!$D:$D,A15,SCHEDULE!$G:$G,"<>")+COUNTIFS(SCHEDULE!$B:$B,"Group E",SCHEDULE!$F:$F,A15,SCHEDULE!$G:$G,"<>") -> 0 | C15: =COUNTIFS(SCHEDULE!$B:$B,"Group E",SCHEDULE!$D:$D,A15,SCHEDULE!$G:$G,A15)+COUNTIFS(SCHEDULE!$B:$B,"Group E",SCHEDULE!$F:$F,A15,SCHEDULE!$G:$G,A15) -> 0 | D15: =COUNTIFS(SCHEDULE!$B:$B,"Group E",SCHEDULE!$D:$D,A15,SCHEDULE!$G:$G,"Draw")+COUNTIFS(SCHEDULE!$B:$B,"Group E",SCHEDULE!$F:$F,A15,SCHEDULE!$G:$G,"Draw") -> 0 | E15: =B15-C15-D15 -> 0 | F15: 0 | G15: =C15*3+D15 -> 0 | H15: =IF(B15=0,"?",RANK(G15,$G$13:$G$16,0)) -> ? | I15: =IF(B15=3,H15,"")
A16: Curacao | B16: =COUNTIFS(SCHEDULE!$B:$B,"Group E",SCHEDULE!$D:$D,A16,SCHEDULE!$G:$G,"<>")+COUNTIFS(SCHEDULE!$B:$B,"Group E",SCHEDULE!$F:$F,A16,SCHEDULE!$G:$G,"<>") -> 0 | C16: =COUNTIFS(SCHEDULE!$B:$B,"Group E",SCHEDULE!$D:$D,A16,SCHEDULE!$G:$G,A16)+COUNTIFS(SCHEDULE!$B:$B,"Group E",SCHEDULE!$F:$F,A16,SCHEDULE!$G:$G,A16) -> 0 | D16: =COUNTIFS(SCHEDULE!$B:$B,"Group E",SCHEDULE!$D:$D,A16,SCHEDULE!$G:$G,"Draw")+COUNTIFS(SCHEDULE!$B:$B,"Group E",SCHEDULE!$F:$F,A16,SCHEDULE!$G:$G,"Draw") -> 0 | E16: =B16-C16-D16 -> 0 | F16: 0 | G16: =C16*3+D16 -> 0 | H16: =IF(B16=0,"?",RANK(G16,$G$13:$G$16,0)) -> ? | I16: =IF(B16=3,H16,"")
A18: GROUP G
A19: Team | B19: Played | C19: W | D19: D | E19: L | F19: GD | G19: Pts | H19: Pos | I19: Confirmed
A20: Belgium | B20: =COUNTIFS(SCHEDULE!$B:$B,"Group G",SCHEDULE!$D:$D,A20,SCHEDULE!$G:$G,"<>")+COUNTIFS(SCHEDULE!$B:$B,"Group G",SCHEDULE!$F:$F,A20,SCHEDULE!$G:$G,"<>") -> 0 | C20: =COUNTIFS(SCHEDULE!$B:$B,"Group G",SCHEDULE!$D:$D,A20,SCHEDULE!$G:$G,A20)+COUNTIFS(SCHEDULE!$B:$B,"Group G",SCHEDULE!$F:$F,A20,SCHEDULE!$G:$G,A20) -> 0 | D20: =COUNTIFS(SCHEDULE!$B:$B,"Group G",SCHEDULE!$D:$D,A20,SCHEDULE!$G:$G,"Draw")+COUNTIFS(SCHEDULE!$B:$B,"Group G",SCHEDULE!$F:$F,A20,SCHEDULE!$G:$G,"Draw") -> 0 | E20: =B20-C20-D20 -> 0 | F20: 0 | G20: =C20*3+D20 -> 0 | H20: =IF(B20=0,"?",RANK(G20,$G$20:$G$23,0)) -> ? | I20: =IF(B20=3,H20,"")
A21: Egypt | B21: =COUNTIFS(SCHEDULE!$B:$B,"Group G",SCHEDULE!$D:$D,A21,SCHEDULE!$G:$G,"<>")+COUNTIFS(SCHEDULE!$B:$B,"Group G",SCHEDULE!$F:$F,A21,SCHEDULE!$G:$G,"<>") -> 0 | C21: =COUNTIFS(SCHEDULE!$B:$B,"Group G",SCHEDULE!$D:$D,A21,SCHEDULE!$G:$G,A21)+COUNTIFS(SCHEDULE!$B:$B,"Group G",SCHEDULE!$F:$F,A21,SCHEDULE!$G:$G,A21) -> 0 | D21: =COUNTIFS(SCHEDULE!$B:$B,"Group G",SCHEDULE!$D:$D,A21,SCHEDULE!$G:$G,"Draw")+COUNTIFS(SCHEDULE!$B:$B,"Group G",SCHEDULE!$F:$F,A21,SCHEDULE!$G:$G,"Draw") -> 0 | E21: =B21-C21-D21 -> 0 | F21: 0 | G21: =C21*3+D21 -> 0 | H21: =IF(B21=0,"?",RANK(G21,$G$20:$G$23,0)) -> ? | I21: =IF(B21=3,H21,"")
A22: Iran | B22: =COUNTIFS(SCHEDULE!$B:$B,"Group G",SCHEDULE!$D:$D,A22,SCHEDULE!$G:$G,"<>")+COUNTIFS(SCHEDULE!$B:$B,"Group G",SCHEDULE!$F:$F,A22,SCHEDULE!$G:$G,"<>") -> 0 | C22: =COUNTIFS(SCHEDULE!$B:$B,"Group G",SCHEDULE!$D:$D,A22,SCHEDULE!$G:$G,A22)+COUNTIFS(SCHEDULE!$B:$B,"Group G",SCHEDULE!$F:$F,A22,SCHEDULE!$G:$G,A22) -> 0 | D22: =COUNTIFS(SCHEDULE!$B:$B,"Group G",SCHEDULE!$D:$D,A22,SCHEDULE!$G:$G,"Draw")+COUNTIFS(SCHEDULE!$B:$B,"Group G",SCHEDULE!$F:$F,A22,SCHEDULE!$G:$G,"Draw") -> 0 | E22: =B22-C22-D22 -> 0 | F22: 0 | G22: =C22*3+D22 -> 0 | H22: =IF(B22=0,"?",RANK(G22,$G$20:$G$23,0)) -> ? | I22: =IF(B22=3,H22,"")
A23: New Zealand | B23: =COUNTIFS(SCHEDULE!$B:$B,"Group G",SCHEDULE!$D:$D,A23,SCHEDULE!$G:$G,"<>")+COUNTIFS(SCHEDULE!$B:$B,"Group G",SCHEDULE!$F:$F,A23,SCHEDULE!$G:$G,"<>") -> 0 | C23: =COUNTIFS(SCHEDULE!$B:$B,"Group G",SCHEDULE!$D:$D,A23,SCHEDULE!$G:$G,A23)+COUNTIFS(SCHEDULE!$B:$B,"Group G",SCHEDULE!$F:$F,A23,SCHEDULE!$G:$G,A23) -> 0 | D23: =COUNTIFS(SCHEDULE!$B:$B,"Group G",SCHEDULE!$D:$D,A23,SCHEDULE!$G:$G,"Draw")+COUNTIFS(SCHEDULE!$B:$B,"Group G",SCHEDULE!$F:$F,A23,SCHEDULE!$G:$G,"Draw") -> 0 | E23: =B23-C23-D23 -> 0 | F23: 0 | G23: =C23*3+D23 -> 0 | H23: =IF(B23=0,"?",RANK(G23,$G$20:$G$23,0)) -> ? | I23: =IF(B23=3,H23,"")
A25: GROUP H
A26: Team | B26: Played | C26: W | D26: D | E26: L | F26: GD | G26: Pts | H26: Pos | I26: Confirmed
A27: Spain | B27: =COUNTIFS(SCHEDULE!$B:$B,"Group H",SCHEDULE!$D:$D,A27,SCHEDULE!$G:$G,"<>")+COUNTIFS(SCHEDULE!$B:$B,"Group H",SCHEDULE!$F:$F,A27,SCHEDULE!$G:$G,"<>") -> 0 | C27: =COUNTIFS(SCHEDULE!$B:$B,"Group H",SCHEDULE!$D:$D,A27,SCHEDULE!$G:$G,A27)+COUNTIFS(SCHEDULE!$B:$B,"Group H",SCHEDULE!$F:$F,A27,SCHEDULE!$G:$G,A27) -> 0 | D27: =COUNTIFS(SCHEDULE!$B:$B,"Group H",SCHEDULE!$D:$D,A27,SCHEDULE!$G:$G,"Draw")+COUNTIFS(SCHEDULE!$B:$B,"Group H",SCHEDULE!$F:$F,A27,SCHEDULE!$G:$G,"Draw") -> 0 | E27: =B27-C27-D27 -> 0 | F27: 0 | G27: =C27*3+D27 -> 0 | H27: =IF(B27=0,"?",RANK(G27,$G$27:$G$30,0)) -> ? | I27: =IF(B27=3,H27,"")
A28: Uruguay | B28: =COUNTIFS(SCHEDULE!$B:$B,"Group H",SCHEDULE!$D:$D,A28,SCHEDULE!$G:$G,"<>")+COUNTIFS(SCHEDULE!$B:$B,"Group H",SCHEDULE!$F:$F,A28,SCHEDULE!$G:$G,"<>") -> 0 | C28: =COUNTIFS(SCHEDULE!$B:$B,"Group H",SCHEDULE!$D:$D,A28,SCHEDULE!$G:$G,A28)+COUNTIFS(SCHEDULE!$B:$B,"Group H",SCHEDULE!$F:$F,A28,SCHEDULE!$G:$G,A28) -> 0 | D28: =COUNTIFS(SCHEDULE!$B:$B,"Group H",SCHEDULE!$D:$D,A28,SCHEDULE!$G:$G,"Draw")+COUNTIFS(SCHEDULE!$B:$B,"Group H",SCHEDULE!$F:$F,A28,SCHEDULE!$G:$G,"Draw") -> 0 | E28: =B28-C28-D28 -> 0 | F28: 0 | G28: =C28*3+D28 -> 0 | H28: =IF(B28=0,"?",RANK(G28,$G$27:$G$30,0)) -> ? | I28: =IF(B28=3,H28,"")
A29: Saudi Arabia | B29: =COUNTIFS(SCHEDULE!$B:$B,"Group H",SCHEDULE!$D:$D,A29,SCHEDULE!$G:$G,"<>")+COUNTIFS(SCHEDULE!$B:$B,"Group H",SCHEDULE!$F:$F,A29,SCHEDULE!$G:$G,"<>") -> 0 | C29: =COUNTIFS(SCHEDULE!$B:$B,"Group H",SCHEDULE!$D:$D,A29,SCHEDULE!$G:$G,A29)+COUNTIFS(SCHEDULE!$B:$B,"Group H",SCHEDULE!$F:$F,A29,SCHEDULE!$G:$G,A29) -> 0 | D29: =COUNTIFS(SCHEDULE!$B:$B,"Group H",SCHEDULE!$D:$D,A29,SCHEDULE!$G:$G,"Draw")+COUNTIFS(SCHEDULE!$B:$B,"Group H",SCHEDULE!$F:$F,A29,SCHEDULE!$G:$G,"Draw") -> 0 | E29: =B29-C29-D29 -> 0 | F29: 0 | G29: =C29*3+D29 -> 0 | H29: =IF(B29=0,"?",RANK(G29,$G$27:$G$30,0)) -> ? | I29: =IF(B29=3,H29,"")
A30: Cape Verde | B30: =COUNTIFS(SCHEDULE!$B:$B,"Group H",SCHEDULE!$D:$D,A30,SCHEDULE!$G:$G,"<>")+COUNTIFS(SCHEDULE!$B:$B,"Group H",SCHEDULE!$F:$F,A30,SCHEDULE!$G:$G,"<>") -> 0 | C30: =COUNTIFS(SCHEDULE!$B:$B,"Group H",SCHEDULE!$D:$D,A30,SCHEDULE!$G:$G,A30)+COUNTIFS(SCHEDULE!$B:$B,"Group H",SCHEDULE!$F:$F,A30,SCHEDULE!$G:$G,A30) -> 0 | D30: =COUNTIFS(SCHEDULE!$B:$B,"Group H",SCHEDULE!$D:$D,A30,SCHEDULE!$G:$G,"Draw")+COUNTIFS(SCHEDULE!$B:$B,"Group H",SCHEDULE!$F:$F,A30,SCHEDULE!$G:$G,"Draw") -> 0 | E30: =B30-C30-D30 -> 0 | F30: 0 | G30: =C30*3+D30 -> 0 | H30: =IF(B30=0,"?",RANK(G30,$G$27:$G$30,0)) -> ? | I30: =IF(B30=3,H30,"")
A32: GROUP I
A33: Team | B33: Played | C33: W | D33: D | E33: L | F33: GD | G33: Pts | H33: Pos | I33: Confirmed
A34: France | B34: =COUNTIFS(SCHEDULE!$B:$B,"Group I",SCHEDULE!$D:$D,A34,SCHEDULE!$G:$G,"<>")+COUNTIFS(SCHEDULE!$B:$B,"Group I",SCHEDULE!$F:$F,A34,SCHEDULE!$G:$G,"<>") -> 0 | C34: =COUNTIFS(SCHEDULE!$B:$B,"Group I",SCHEDULE!$D:$D,A34,SCHEDULE!$G:$G,A34)+COUNTIFS(SCHEDULE!$B:$B,"Group I",SCHEDULE!$F:$F,A34,SCHEDULE!$G:$G,A34) -> 0 | D34: =COUNTIFS(SCHEDULE!$B:$B,"Group I",SCHEDULE!$D:$D,A34,SCHEDULE!$G:$G,"Draw")+COUNTIFS(SCHEDULE!$B:$B,"Group I",SCHEDULE!$F:$F,A34,SCHEDULE!$G:$G,"Draw") -> 0 | E34: =B34-C34-D34 -> 0 | F34: 0 | G34: =C34*3+D34 -> 0 | H34: =IF(B34=0,"?",RANK(G34,$G$34:$G$37,0)) -> ? | I34: =IF(B34=3,H34,"")
A35: Senegal | B35: =COUNTIFS(SCHEDULE!$B:$B,"Group I",SCHEDULE!$D:$D,A35,SCHEDULE!$G:$G,"<>")+COUNTIFS(SCHEDULE!$B:$B,"Group I",SCHEDULE!$F:$F,A35,SCHEDULE!$G:$G,"<>") -> 0 | C35: =COUNTIFS(SCHEDULE!$B:$B,"Group I",SCHEDULE!$D:$D,A35,SCHEDULE!$G:$G,A35)+COUNTIFS(SCHEDULE!$B:$B,"Group I",SCHEDULE!$F:$F,A35,SCHEDULE!$G:$G,A35) -> 0 | D35: =COUNTIFS(SCHEDULE!$B:$B,"Group I",SCHEDULE!$D:$D,A35,SCHEDULE!$G:$G,"Draw")+COUNTIFS(SCHEDULE!$B:$B,"Group I",SCHEDULE!$F:$F,A35,SCHEDULE!$G:$G,"Draw") -> 0 | E35: =B35-C35-D35 -> 0 | F35: 0 | G35: =C35*3+D35 -> 0 | H35: =IF(B35=0,"?",RANK(G35,$G$34:$G$37,0)) -> ? | I35: =IF(B35=3,H35,"")
A36: Norway | B36: =COUNTIFS(SCHEDULE!$B:$B,"Group I",SCHEDULE!$D:$D,A36,SCHEDULE!$G:$G,"<>")+COUNTIFS(SCHEDULE!$B:$B,"Group I",SCHEDULE!$F:$F,A36,SCHEDULE!$G:$G,"<>") -> 0 | C36: =COUNTIFS(SCHEDULE!$B:$B,"Group I",SCHEDULE!$D:$D,A36,SCHEDULE!$G:$G,A36)+COUNTIFS(SCHEDULE!$B:$B,"Group I",SCHEDULE!$F:$F,A36,SCHEDULE!$G:$G,A36) -> 0 | D36: =COUNTIFS(SCHEDULE!$B:$B,"Group I",SCHEDULE!$D:$D,A36,SCHEDULE!$G:$G,"Draw")+COUNTIFS(SCHEDULE!$B:$B,"Group I",SCHEDULE!$F:$F,A36,SCHEDULE!$G:$G,"Draw") -> 0 | E36: =B36-C36-D36 -> 0 | F36: 0 | G36: =C36*3+D36 -> 0 | H36: =IF(B36=0,"?",RANK(G36,$G$34:$G$37,0)) -> ? | I36: =IF(B36=3,H36,"")
A37: TBD_I4 | B37: =COUNTIFS(SCHEDULE!$B:$B,"Group I",SCHEDULE!$D:$D,A37,SCHEDULE!$G:$G,"<>")+COUNTIFS(SCHEDULE!$B:$B,"Group I",SCHEDULE!$F:$F,A37,SCHEDULE!$G:$G,"<>") -> 0 | C37: =COUNTIFS(SCHEDULE!$B:$B,"Group I",SCHEDULE!$D:$D,A37,SCHEDULE!$G:$G,A37)+COUNTIFS(SCHEDULE!$B:$B,"Group I",SCHEDULE!$F:$F,A37,SCHEDULE!$G:$G,A37) -> 0 | D37: =COUNTIFS(SCHEDULE!$B:$B,"Group I",SCHEDULE!$D:$D,A37,SCHEDULE!$G:$G,"Draw")+COUNTIFS(SCHEDULE!$B:$B,"Group I",SCHEDULE!$F:$F,A37,SCHEDULE!$G:$G,"Draw") -> 0 | E37: =B37-C37-D37 -> 0 | F37: 0 | G37: =C37*3+D37 -> 0 | H37: =IF(B37=0,"?",RANK(G37,$G$34:$G$37,0)) -> ? | I37: =IF(B37=3,H37,"")
A39: GROUP J
A40: Team | B40: Played | C40: W | D40: D | E40: L | F40: GD | G40: Pts | H40: Pos | I40: Confirmed
A41: Argentina | B41: =COUNTIFS(SCHEDULE!$B:$B,"Group J",SCHEDULE!$D:$D,A41,SCHEDULE!$G:$G,"<>")+COUNTIFS(SCHEDULE!$B:$B,"Group J",SCHEDULE!$F:$F,A41,SCHEDULE!$G:$G,"<>") -> 0 | C41: =COUNTIFS(SCHEDULE!$B:$B,"Group J",SCHEDULE!$D:$D,A41,SCHEDULE!$G:$G,A41)+COUNTIFS(SCHEDULE!$B:$B,"Group J",SCHEDULE!$F:$F,A41,SCHEDULE!$G:$G,A41) -> 0 | D41: =COUNTIFS(SCHEDULE!$B:$B,"Group J",SCHEDULE!$D:$D,A41,SCHEDULE!$G:$G,"Draw")+COUNTIFS(SCHEDULE!$B:$B,"Group J",SCHEDULE!$F:$F,A41,SCHEDULE!$G:$G,"Draw") -> 0 | E41: =B41-C41-D41 -> 0 | F41: 0 | G41: =C41*3+D41 -> 0 | H41: =IF(B41=0,"?",RANK(G41,$G$41:$G$44,0)) -> ? | I41: =IF(B41=3,H41,"")
A42: Austria | B42: =COUNTIFS(SCHEDULE!$B:$B,"Group J",SCHEDULE!$D:$D,A42,SCHEDULE!$G:$G,"<>")+COUNTIFS(SCHEDULE!$B:$B,"Group J",SCHEDULE!$F:$F,A42,SCHEDULE!$G:$G,"<>") -> 0 | C42: =COUNTIFS(SCHEDULE!$B:$B,"Group J",SCHEDULE!$D:$D,A42,SCHEDULE!$G:$G,A42)+COUNTIFS(SCHEDULE!$B:$B,"Group J",SCHEDULE!$F:$F,A42,SCHEDULE!$G:$G,A42) -> 0 | D42: =COUNTIFS(SCHEDULE!$B:$B,"Group J",SCHEDULE!$D:$D,A42,SCHEDULE!$G:$G,"Draw")+COUNTIFS(SCHEDULE!$B:$B,"Group J",SCHEDULE!$F:$F,A42,SCHEDULE!$G:$G,"Draw") -> 0 | E42: =B42-C42-D42 -> 0 | F42: 0 | G42: =C42*3+D42 -> 0 | H42: =IF(B42=0,"?",RANK(G42,$G$41:$G$44,0)) -> ? | I42: =IF(B42=3,H42,"")
A43: Jordan | B43: =COUNTIFS(SCHEDULE!$B:$B,"Group J",SCHEDULE!$D:$D,A43,SCHEDULE!$G:$G,"<>")+COUNTIFS(SCHEDULE!$B:$B,"Group J",SCHEDULE!$F:$F,A43,SCHEDULE!$G:$G,"<>") -> 0 | C43: =COUNTIFS(SCHEDULE!$B:$B,"Group J",SCHEDULE!$D:$D,A43,SCHEDULE!$G:$G,A43)+COUNTIFS(SCHEDULE!$B:$B,"Group J",SCHEDULE!$F:$F,A43,SCHEDULE!$G:$G,A43) -> 0 | D43: =COUNTIFS(SCHEDULE!$B:$B,"Group J",SCHEDULE!$D:$D,A43,SCHEDULE!$G:$G,"Draw")+COUNTIFS(SCHEDULE!$B:$B,"Group J",SCHEDULE!$F:$F,A43,SCHEDULE!$G:$G,"Draw") -> 0 | E43: =B43-C43-D43 -> 0 | F43: 0 | G43: =C43*3+D43 -> 0 | H43: =IF(B43=0,"?",RANK(G43,$G$41:$G$44,0)) -> ? | I43: =IF(B43=3,H43,"")
A44: Algeria | B44: =COUNTIFS(SCHEDULE!$B:$B,"Group J",SCHEDULE!$D:$D,A44,SCHEDULE!$G:$G,"<>")+COUNTIFS(SCHEDULE!$B:$B,"Group J",SCHEDULE!$F:$F,A44,SCHEDULE!$G:$G,"<>") -> 0 | C44: =COUNTIFS(SCHEDULE!$B:$B,"Group J",SCHEDULE!$D:$D,A44,SCHEDULE!$G:$G,A44)+COUNTIFS(SCHEDULE!$B:$B,"Group J",SCHEDULE!$F:$F,A44,SCHEDULE!$G:$G,A44) -> 0 | D44: =COUNTIFS(SCHEDULE!$B:$B,"Group J",SCHEDULE!$D:$D,A44,SCHEDULE!$G:$G,"Draw")+COUNTIFS(SCHEDULE!$B:$B,"Group J",SCHEDULE!$F:$F,A44,SCHEDULE!$G:$G,"Draw") -> 0 | E44: =B44-C44-D44 -> 0 | F44: 0 | G44: =C44*3+D44 -> 0 | H44: =IF(B44=0,"?",RANK(G44,$G$41:$G$44,0)) -> ? | I44: =IF(B44=3,H44,"")
A46: GROUP K
A47: Team | B47: Played | C47: W | D47: D | E47: L | F47: GD | G47: Pts | H47: Pos | I47: Confirmed
...

Sheet CALC
A1: POSITION PROBABILITY CALCULATOR
A2: Q = W + P(2nd) + 0.67×P(3rd) → Corrected for 3rd place qualifiers (8/12 = 67%)
A3: α = strength factor. Strong teams: α→1 (Q-W is mostly P(2nd)). Weak teams: α→0 (Q-W is mostly P(3rd))
A5: Grp | B5: Team | C5: W% | D5: Q% | E5: α (strength) | F5: P(2nd)+0.67P(3rd) | G5: P(2nd) Calc | H5: Pts Pos | I5: Final P(1st) | J5: Final P(2nd) | K5: Source
A6: D | B6: United States | C6: =INDEX(ODDS!$D$6:$D$44,MATCH(B6,ODDS!$B$6:$B$44,0)) -> 43.518519 | D6: =INDEX(ODDS!$C$49:$C$87,MATCH(B6,ODDS!$B$49:$B$87,0)) -> 82 | E6: =C6/(C6+(SUMIF($A$6:$A$9,$A6,$C$6:$C$9)-C6)/3) -> 0.6980198 | F6: =D6-C6 -> 38.481481 | G6: =E6*(D6-C6)/(0.67+0.33*E6)/100 -> 0.29833886 | H6: =POINTS!I6 | I6: =IF(H6=1,1,IF(AND(H6<>"",H6<>"?"),0,C6/100)) -> 0.43518519 | J6: =IF(H6=2,1,IF(AND(H6<>"",H6<>"?"),0,G6)) -> 0.29833886 | K6: =IF(AND(H6<>"",H6<>"?"),"CONFIRMED","Market") -> Market
A7: D | B7: Paraguay | C7: =INDEX(ODDS!$D$6:$D$44,MATCH(B7,ODDS!$B$6:$B$44,0)) -> 21.296296 | D7: =INDEX(ODDS!$C$49:$C$87,MATCH(B7,ODDS!$B$49:$B$87,0)) -> 62 | E7: =C7/(C7+(SUMIF($A$6:$A$9,$A7,$C$6:$C$9)-C7)/3) -> 0.44805195 | F7: =D7-C7 -> 40.703704 | G7: =E7*(D7-C7)/(0.67+0.33*E7)/100 -> 0.22298972 | H7: =POINTS!I7 | I7: =IF(H7=1,1,IF(AND(H7<>"",H7<>"?"),0,C7/100)) -> 0.21296296 | J7: =IF(H7=2,1,IF(AND(H7<>"",H7<>"?"),0,G7)) -> 0.22298972 | K7: =IF(AND(H7<>"",H7<>"?"),"CONFIRMED","Market") -> Market
A8: D | B8: Australia | C8: =INDEX(ODDS!$D$6:$D$44,MATCH(B8,ODDS!$B$6:$B$44,0)) -> 13.888889 | D8: =INDEX(ODDS!$C$49:$C$87,MATCH(B8,ODDS!$B$49:$B$87,0)) -> 48 | E8: =C8/(C8+(SUMIF($A$6:$A$9,$A8,$C$6:$C$9)-C8)/3) -> 0.32608696 | F8: =D8-C8 -> 34.111111 | G8: =E8*(D8-C8)/(0.67+0.33*E8)/100 -> 0.14304352 | H8: =POINTS!I8 | I8: =IF(H8=1,1,IF(AND(H8<>"",H8<>"?"),0,C8/100)) -> 0.13888889 | J8: =IF(H8=2,1,IF(AND(H8<>"",H8<>"?"),0,G8)) -> 0.14304352 | K8: =IF(AND(H8<>"",H8<>"?"),"CONFIRMED","Market") -> Market
A9: D | B9: TBD_C | C9: =INDEX(ODDS!$D$6:$D$44,MATCH(B9,ODDS!$B$6:$B$44,0)) -> 21.296296 | D9: =INDEX(ODDS!$C$49:$C$87,MATCH(B9,ODDS!$B$49:$B$87,0)) -> 49 | E9: =C9/(C9+(SUMIF($A$6:$A$9,$A9,$C$6:$C$9)-C9)/3) -> 0.44805195 | F9: =D9-C9 -> 27.703704 | G9: =E9*(D9-C9)/(0.67+0.33*E9)/100 -> 0.15177098 | H9: =POINTS!I9 | I9: =IF(H9=1,1,IF(AND(H9<>"",H9<>"?"),0,C9/100)) -> 0.21296296 | J9: =IF(H9=2,1,IF(AND(H9<>"",H9<>"?"),0,G9)) -> 0.15177098 | K9: =IF(AND(H9<>"",H9<>"?"),"CONFIRMED","Market") -> Market
A11: E | B11: Germany | C11: =INDEX(ODDS!$D$6:$D$44,MATCH(B11,ODDS!$B$6:$B$44,0)) -> 69.473684 | D11: =INDEX(ODDS!$C$49:$C$87,MATCH(B11,ODDS!$B$49:$B$87,0)) -> 97 | E11: =C11/(C11+(SUMIF($A$11:$A$14,$A11,$C$11:$C$14)-C11)/3) -> 0.8722467 | F11: =D11-C11 -> 27.526316 | G11: =E11*(D11-C11)/(0.67+0.33*E11)/100 -> 0.25066507 | H11: =POINTS!I13 | I11: =IF(H11=1,1,IF(AND(H11<>"",H11<>"?"),0,C11/100)) -> 0.69473684 | J11: =IF(H11=2,1,IF(AND(H11<>"",H11<>"?"),0,G11)) -> 0.25066507 | K11: =IF(AND(H11<>"",H11<>"?"),"CONFIRMED","Market") -> Market
A12: E | B12: Ecuador | C12: =INDEX(ODDS!$D$6:$D$44,MATCH(B12,ODDS!$B$6:$B$44,0)) -> 18.947368 | D12: =INDEX(ODDS!$C$49:$C$87,MATCH(B12,ODDS!$B$49:$B$87,0)) -> 88 | E12: =C12/(C12+(SUMIF($A$11:$A$14,$A12,$C$11:$C$14)-C12)/3) -> 0.41221374 | F12: =D12-C12 -> 69.052632 | G12: =E12*(D12-C12)/(0.67+0.33*E12)/100 -> 0.35314349 | H12: =POINTS!I14 | I12: =IF(H12=1,1,IF(AND(H12<>"",H12<>"?"),0,C12/100)) -> 0.18947368 | J12: =IF(H12=2,1,IF(AND(H12<>"",H12<>"?"),0,G12)) -> 0.35314349 | K12: =IF(AND(H12<>"",H12<>"?"),"CONFIRMED","Market") -> Market
A13: E | B13: Ivory Coast | C13: =INDEX(ODDS!$D$6:$D$44,MATCH(B13,ODDS!$B$6:$B$44,0)) -> 10.526316 | D13: =INDEX(ODDS!$C$49:$C$87,MATCH(B13,ODDS!$B$49:$B$87,0)) -> 73 | E13: =C13/(C13+(SUMIF($A$11:$A$14,$A13,$C$11:$C$14)-C13)/3) -> 0.26086957 | F13: =D13-C13 -> 62.473684 | G13: =E13*(D13-C13)/(0.67+0.33*E13)/100 -> 0.21555038 | H13: =POINTS!I15 | I13: =IF(H13=1,1,IF(AND(H13<>"",H13<>"?"),0,C13/100)) -> 0.10526316 | J13: =IF(H13=2,1,IF(AND(H13<>"",H13<>"?"),0,G13)) -> 0.21555038 | K13: =IF(AND(H13<>"",H13<>"?"),"CONFIRMED","Market") -> Market
A14: E | B14: Curacao | C14: =INDEX(ODDS!$D$6:$D$44,MATCH(B14,ODDS!$B$6:$B$44,0)) -> 1.0526316 | D14: =INDEX(ODDS!$C$49:$C$87,MATCH(B14,ODDS!$B$49:$B$87,0)) -> 13 | E14: =C14/(C14+(SUMIF($A$11:$A$14,$A14,$C$11:$C$14)-C14)/3) -> 0.030927835 | F14: =D14-C14 -> 11.947368 | G14: =E14*(D14-C14)/(0.67+0.33*E14)/100 -> 0.0054322682 | H14: =POINTS!I16 | I14: =IF(H14=1,1,IF(AND(H14<>"",H14<>"?"),0,C14/100)) -> 0.010526316 | J14: =IF(H14=2,1,IF(AND(H14<>"",H14<>"?"),0,G14)) -> 0.0054322682 | K14: =IF(AND(H14<>"",H14<>"?"),"CONFIRMED","Market") -> Market
A16: G | B16: Belgium | C16: =INDEX(ODDS!$D$6:$D$44,MATCH(B16,ODDS!$B$6:$B$44,0)) -> 68.686869 | D16: =INDEX(ODDS!$C$49:$C$87,MATCH(B16,ODDS!$B$49:$B$87,0)) -> 95 | E16: =C16/(C16+(SUMIF($A$16:$A$19,$A16,$C$16:$C$19)-C16)/3) -> 0.86808511 | F16: =D16-C16 -> 26.313131 | G16: =E16*(D16-C16)/(0.67+0.33*E16)/100 -> 0.23881651 | H16: =POINTS!I20 | I16: =IF(H16=1,1,IF(AND(H16<>"",H16<>"?"),0,C16/100)) -> 0.68686869 | J16: =IF(H16=2,1,IF(AND(H16<>"",H16<>"?"),0,G16)) -> 0.23881651 | K16: =IF(AND(H16<>"",H16<>"?"),"CONFIRMED","Market") -> Market
A17: G | B17: Egypt | C17: =INDEX(ODDS!$D$6:$D$44,MATCH(B17,ODDS!$B$6:$B$44,0)) -> 18.181818 | D17: =INDEX(ODDS!$C$49:$C$87,MATCH(B17,ODDS!$B$49:$B$87,0)) -> 58 | E17: =C17/(C17+(SUMIF($A$16:$A$19,$A17,$C$16:$C$19)-C17)/3) -> 0.4 | F17: =D17-C17 -> 39.818182 | G17: =E17*(D17-C17)/(0.67+0.33*E17)/100 -> 0.19859442 | H17: =POINTS!I21 | I17: =IF(H17=1,1,IF(AND(H17<>"",H17<>"?"),0,C17/100)) -> 0.18181818 | J17: =IF(H17=2,1,IF(AND(H17<>"",H17<>"?"),0,G17)) -> 0.19859442 | K17: =IF(AND(H17<>"",H17<>"?"),"CONFIRMED","Market") -> Market
A18: G | B18: Iran | C18: =INDEX(ODDS!$D$6:$D$44,MATCH(B18,ODDS!$B$6:$B$44,0)) -> 8.0808081 | D18: =INDEX(ODDS!$C$49:$C$87,MATCH(B18,ODDS!$B$49:$B$87,0)) -> 35 | E18: =C18/(C18+(SUMIF($A$16:$A$19,$A18,$C$16:$C$19)-C18)/3) -> 0.20869565 | F18: =D18-C18 -> 26.919192 | G18: =E18*(D18-C18)/(0.67+0.33*E18)/100 -> 0.076033966 | H18: =POINTS!I22 | I18: =IF(H18=1,1,IF(AND(H18<>"",H18<>"?"),0,C18/100)) -> 0.080808081 | J18: =IF(H18=2,1,IF(AND(H18<>"",H18<>"?"),0,G18)) -> 0.076033966 | K18: =IF(AND(H18<>"",H18<>"?"),"CONFIRMED","Market") -> Market
A19: G | B19: New Zealand | C19: =INDEX(ODDS!$D$6:$D$44,MATCH(B19,ODDS!$B$6:$B$44,0)) -> 5.0505051 | D19: =INDEX(ODDS!$C$49:$C$87,MATCH(B19,ODDS!$B$49:$B$87,0)) -> 12 | E19: =C19/(C19+(SUMIF($A$16:$A$19,$A19,$C$16:$C$19)-C19)/3) -> 0.13761468 | F19: =D19-C19 -> 6.9494949 | G19: =E19*(D19-C19)/(0.67+0.33*E19)/100 -> 0.013367841 | H19: =POINTS!I23 | I19: =IF(H19=1,1,IF(AND(H19<>"",H19<>"?"),0,C19/100)) -> 0.050505051 | J19: =IF(H19=2,1,IF(AND(H19<>"",H19<>"?"),0,G19)) -> 0.013367841 | K19: =IF(AND(H19<>"",H19<>"?"),"CONFIRMED","Market") -> Market
A21: H | B21: Spain | C21: =INDEX(ODDS!$D$6:$D$44,MATCH(B21,ODDS!$B$6:$B$44,0)) -> 77.45098 | D21: =INDEX(ODDS!$C$49:$C$87,MATCH(B21,ODDS!$B$49:$B$87,0)) -> 98 | E21: =C21/(C21+(SUMIF($A$21:$A$24,$A21,$C$21:$C$24)-C21)/3) -> 0.91153846 | F21: =D21-C21 -> 20.54902 | G21: =E21*(D21-C21)/(0.67+0.33*E21)/100 -> 0.19294472 | H21: =POINTS!I27 | I21: =IF(H21=1,1,IF(AND(H21<>"",H21<>"?"),0,C21/100)) -> 0.7745098 | J21: =IF(H21=2,1,IF(AND(H21<>"",H21<>"?"),0,G21)) -> 0.19294472 | K21: =IF(AND(H21<>"",H21<>"?"),"CONFIRMED","Market") -> Market
A22: H | B22: Uruguay | C22: =INDEX(ODDS!$D$6:$D$44,MATCH(B22,ODDS!$B$6:$B$44,0)) -> 14.705882 | D22: =INDEX(ODDS!$C$49:$C$87,MATCH(B22,ODDS!$B$49:$B$87,0)) -> 72 | E22: =C22/(C22+(SUMIF($A$21:$A$24,$A22,$C$21:$C$24)-C22)/3) -> 0.34090909 | F22: =D22-C22 -> 57.294118 | G22: =E22*(D22-C22)/(0.67+0.33*E22)/100 -> 0.24961132 | H22: =POINTS!I28 | I22: =IF(H22=1,1,IF(AND(H22<>"",H22<>"?"),0,C22/100)) -> 0.14705882 | J22: =IF(H22=2,1,IF(AND(H22<>"",H22<>"?"),0,G22)) -> 0.24961132 | K22: =IF(AND(H22<>"",H22<>"?"),"CONFIRMED","Market") -> Market
A23: H | B23: Saudi Arabia | C23: =INDEX(ODDS!$D$6:$D$44,MATCH(B23,ODDS!$B$6:$B$44,0)) -> 3.9215686 | D23: =INDEX(ODDS!$C$49:$C$87,MATCH(B23,ODDS!$B$49:$B$87,0)) -> 22 | E23: =C23/(C23+(SUMIF($A$21:$A$24,$A23,$C$21:$C$24)-C23)/3) -> 0.10909091 | F23: =D23-C23 -> 18.078431 | G23: =E23*(D23-C23)/(0.67+0.33*E23)/100 -> 0.027934738 | H23: =POINTS!I29 | I23: =IF(H23=1,1,IF(AND(H23<>"",H23<>"?"),0,C23/100)) -> 0.039215686 | J23: =IF(H23=2,1,IF(AND(H23<>"",H23<>"?"),0,G23)) -> 0.027934738 | K23: =IF(AND(H23<>"",H23<>"?"),"CONFIRMED","Market") -> Market
A24: H | B24: Cape Verde | C24: =INDEX(ODDS!$D$6:$D$44,MATCH(B24,ODDS!$B$6:$B$44,0)) -> 3.9215686 | D24: =INDEX(ODDS!$C$49:$C$87,MATCH(B24,ODDS!$B$49:$B$87,0)) -> 8 | E24: =C24/(C24+(SUMIF($A$21:$A$24,$A24,$C$21:$C$24)-C24)/3) -> 0.10909091 | F24: =D24-C24 -> 4.0784314 | G24: =E24*(D24-C24)/(0.67+0.33*E24)/100 -> 0.00630198 | H24: =POINTS!I30 | I24: =IF(H24=1,1,IF(AND(H24<>"",H24<>"?"),0,C24/100)) -> 0.039215686 | J24: =IF(H24=2,1,IF(AND(H24<>"",H24<>"?"),0,G24)) -> 0.00630198 | K24: =IF(AND(H24<>"",H24<>"?"),"CONFIRMED","Market") -> Market
A26: I | B26: France | C26: =INDEX(ODDS!$D$6:$D$44,MATCH(B26,ODDS!$B$6:$B$44,0)) -> 68.316832 | D26: =INDEX(ODDS!$C$49:$C$87,MATCH(B26,ODDS!$B$49:$B$87,0)) -> 94 | E26: =C26/(C26+(SUMIF($A$26:$A$29,$A26,$C$26:$C$29)-C26)/3) -> 0.86610879 | F26: =D26-C26 -> 25.683168 | G26: =E26*(D26-C26)/(0.67+0.33*E26)/100 -> 0.23272701 | H26: =POINTS!I34 | I26: =IF(H26=1,1,IF(AND(H26<>"",H26<>"?"),0,C26/100)) -> 0.68316832 | J26: =IF(H26=2,1,IF(AND(H26<>"",H26<>"?"),0,G26)) -> 0.23272701 | K26: =IF(AND(H26<>"",H26<>"?"),"CONFIRMED","Market") -> Market
A27: I | B27: Senegal | C27: =INDEX(ODDS!$D$6:$D$44,MATCH(B27,ODDS!$B$6:$B$44,0)) -> 8.9108911 | D27: =INDEX(ODDS!$C$49:$C$87,MATCH(B27,ODDS!$B$49:$B$87,0)) -> 64 | E27: =C27/(C27+(SUMIF($A$26:$A$29,$A27,$C$26:$C$29)-C27)/3) -> 0.22689076 | F27: =D27-C27 -> 55.089109 | G27: =E27*(D27-C27)/(0.67+0.33*E27)/100 -> 0.16780302 | H27: =POINTS!I35 | I27: =IF(H27=1,1,IF(AND(H27<>"",H27<>"?"),0,C27/100)) -> 0.089108911 | J27: =IF(H27=2,1,IF(AND(H27<>"",H27<>"?"),0,G27)) -> 0.16780302 | K27: =IF(AND(H27<>"",H27<>"?"),"CONFIRMED","Market") -> Market
A28: I | B28: Norway | C28: =INDEX(ODDS!$D$6:$D$44,MATCH(B28,ODDS!$B$6:$B$44,0)) -> 21.782178 | D28: =INDEX(ODDS!$C$49:$C$87,MATCH(B28,ODDS!$B$49:$B$87,0)) -> 78 | E28: =C28/(C28+(SUMIF($A$26:$A$29,$A28,$C$26:$C$29)-C28)/3) -> 0.45517241 | F28: =D28-C28 -> 56.217822 | G28: =E28*(D28-C28)/(0.67+0.33*E28)/100 -> 0.31197984 | H28: =POINTS!I36 | I28: =IF(H28=1,1,IF(AND(H28<>"",H28<>"?"),0,C28/100)) -> 0.21782178 | J28: =IF(H28=2,1,IF(AND(H28<>"",H28<>"?"),0,G28)) -> 0.31197984 | K28: =IF(AND(H28<>"",H28<>"?"),"CONFIRMED","Market") -> Market
A29: I | B29: TBD_I4 | C29: =INDEX(ODDS!$D$6:$D$44,MATCH(B29,ODDS!$B$6:$B$44,0)) -> 0.99009901 | D29: =INDEX(ODDS!$C$49:$C$87,MATCH(B29,ODDS!$B$49:$B$87,0)) -> 10 | E29: =C29/(C29+(SUMIF($A$26:$A$29,$A29,$C$26:$C$29)-C29)/3) -> 0.029126214 | F29: =D29-C29 -> 9.009901 | G29: =E29*(D29-C29)/(0.67+0.33*E29)/100 -> 0.0038613861 | H29: =POINTS!I37 | I29: =IF(H29=1,1,IF(AND(H29<>"",H29<>"?"),0,C29/100)) -> 0.0099009901 | J29: =IF(H29=2,1,IF(AND(H29<>"",H29<>"?"),0,G29)) -> 0.0038613861 | K29: =IF(AND(H29<>"",H29<>"?"),"CONFIRMED","Market") -> Market
A31: J | B31: Argentina | C31: =INDEX(ODDS!$D$6:$D$44,MATCH(B31,ODDS!$B$6:$B$44,0)) -> 68.807339 | D31: =INDEX(ODDS!$C$49:$C$87,MATCH(B31,ODDS!$B$49:$B$87,0)) -> 97 | E31: =C31/(C31+(SUMIF($A$31:$A$34,$A31,$C$31:$C$34)-C31)/3) -> 0.86872587 | F31: =D31-C31 -> 28.192661 | G31: =E31*(D31-C31)/(0.67+0.33*E31)/100 -> 0.25600729 | H31: =POINTS!I41 | I31: =IF(H31=1,1,IF(AND(H31<>"",H31<>"?"),0,C31/100)) -> 0.68807339 | J31: =IF(H31=2,1,IF(AND(H31<>"",H31<>"?"),0,G31)) -> 0.25600729 | K31: =IF(AND(H31<>"",H31<>"?"),"CONFIRMED","Market") -> Market
A32: J | B32: Austria | C32: =INDEX(ODDS!$D$6:$D$44,MATCH(B32,ODDS!$B$6:$B$44,0)) -> 16.513761 | D32: =INDEX(ODDS!$C$49:$C$87,MATCH(B32,ODDS!$B$49:$B$87,0)) -> 74 | E32: =C32/(C32+(SUMIF($A$31:$A$34,$A32,$C$31:$C$34)-C32)/3) -> 0.37241379 | F32: =D32-C32 -> 57.486239 | G32: =E32*(D32-C32)/(0.67+0.33*E32)/100 -> 0.27000582 | H32: =POINTS!I42 | I32: =IF(H32=1,1,IF(AND(H32<>"",H32<>"?"),0,C32/100)) -> 0.16513761 | J32: =IF(H32=2,1,IF(AND(H32<>"",H32<>"?"),0,G32)) -> 0.27000582 | K32: =IF(AND(H32<>"",H32<>"?"),"CONFIRMED","Market") -> Market
A33: J | B33: Jordan | C33: =INDEX(ODDS!$D$6:$D$44,MATCH(B33,ODDS!$B$6:$B$44,0)) -> 4.587156 | D33: =INDEX(ODDS!$C$49:$C$87,MATCH(B33,ODDS!$B$49:$B$87,0)) -> 32 | E33: =C33/(C33+(SUMIF($A$31:$A$34,$A33,$C$31:$C$34)-C33)/3) -> 0.12605042 | F33: =D33-C33 -> 27.412844 | G33: =E33*(D33-C33)/(0.67+0.33*E33)/100 -> 0.048558415 | H33: =POINTS!I43 | I33: =IF(H33=1,1,IF(AND(H33<>"",H33<>"?"),0,C33/100)) -> 0.04587156 | J33: =IF(H33=2,1,IF(AND(H33<>"",H33<>"?"),0,G33)) -> 0.048558415 | K33: =IF(AND(H33<>"",H33<>"?"),"CONFIRMED","Market") -> Market
A34: J | B34: Algeria | C34: =INDEX(ODDS!$D$6:$D$44,MATCH(B34,ODDS!$B$6:$B$44,0)) -> 10.091743 | D34: =INDEX(ODDS!$C$49:$C$87,MATCH(B34,ODDS!$B$49:$B$87,0)) -> 64 | E34: =C34/(C34+(SUMIF($A$31:$A$34,$A34,$C$31:$C$34)-C34)/3) -> 0.2519084 | F34: =D34-C34 -> 53.908257 | G34: =E34*(D34-C34)/(0.67+0.33*E34)/100 -> 0.18031345 | H34: =POINTS!I44 | I34: =IF(H34=1,1,IF(AND(H34<>"",H34<>"?"),0,C34/100)) -> 0.10091743 | J34: =IF(H34=2,1,IF(AND(H34<>"",H34<>"?"),0,G34)) -> 0.18031345 | K34: =IF(AND(H34<>"",H34<>"?"),"CONFIRMED","Market") -> Market
A36: K | B36: Portugal | C36: =INDEX(ODDS!$D$6:$D$44,MATCH(B36,ODDS!$B$6:$B$44,0)) -> 66.990291 | D36: =INDEX(ODDS!$C$49:$C$87,MATCH(B36,ODDS!$B$49:$B$87,0)) -> 92 | E36: =C36/(C36+(SUMIF($A$36:$A$39,$A36,$C$36:$C$39)-C36)/3) -> 0.85892116 | F36: =D36-C36 -> 25.009709 | G36: =E36*(D36-C36)/(0.67+0.33*E36)/100 -> 0.22530289 | H36: =POINTS!I48 | I36: =IF(H36=1,1,IF(AND(H36<>"",H36<>"?"),0,C36/100)) -> 0.66990291 | J36: =IF(H36=2,1,IF(AND(H36<>"",H36<>"?"),0,G36)) -> 0.22530289 | K36: =IF(AND(H36<>"",H36<>"?"),"CONFIRMED","Market") -> Market
A37: K | B37: Colombia | C37: =INDEX(ODDS!$D$6:$D$44,MATCH(B37,ODDS!$B$6:$B$44,0)) -> 30.097087 | D37: =INDEX(ODDS!$C$49:$C$87,MATCH(B37,ODDS!$B$49:$B$87,0)) -> 85 | E37: =C37/(C37+(SUMIF($A$36:$A$39,$A37,$C$36:$C$39)-C37)/3) -> 0.56363636 | F37: =D37-C37 -> 54.902913 | G37: =E37*(D37-C37)/(0.67+0.33*E37)/100 -> 0.36151026 | H37: =POINTS!I49 | I37: =IF(H37=1,1,IF(AND(H37<>"",H37<>"?"),0,C37/100)) -> 0.30097087 | J37: =IF(H37=2,1,IF(AND(H37<>"",H37<>"?"),0,G37)) -> 0.36151026 | K37: =IF(AND(H37<>"",H37<>"?"),"CONFIRMED","Market") -> Market
A38: K | B38: Uzbekistan | C38: =INDEX(ODDS!$D$6:$D$44,MATCH(B38,ODDS!$B$6:$B$44,0)) -> 1.9417476 | D38: =INDEX(ODDS!$C$49:$C$87,MATCH(B38,ODDS!$B$49:$B$87,0)) -> 29 | E38: =C38/(C38+(SUMIF($A$36:$A$39,$A38,$C$36:$C$39)-C38)/3) -> 0.056074766 | F38: =D38-C38 -> 27.058252 | G38: =E38*(D38-C38)/(0.67+0.33*E38)/100 -> 0.022037398 | H38: =POINTS!I50 | I38: =IF(H38=1,1,IF(AND(H38<>"",H38<>"?"),0,C38/100)) -> 0.019417476 | J38: =IF(H38=2,1,IF(AND(H38<>"",H38<>"?"),0,G38)) -> 0.022037398 | K38: =IF(AND(H38<>"",H38<>"?"),"CONFIRMED","Market") -> Market
A39: K | B39: TBD_K4 | C39: =INDEX(ODDS!$D$6:$D$44,MATCH(B39,ODDS!$B$6:$B$44,0)) -> 0.97087379 | D39: =INDEX(ODDS!$C$49:$C$87,MATCH(B39,ODDS!$B$49:$B$87,0)) -> 10 | E39: =C39/(C39+(SUMIF($A$36:$A$39,$A39,$C$36:$C$39)-C39)/3) -> 0.028571429 | F39: =D39-C39 -> 9.0291262 | G39: =E39*(D39-C39)/(0.67+0.33*E39)/100 -> 0.0037969412 | H39: =POINTS!I51 | I39: =IF(H39=1,1,IF(AND(H39<>"",H39<>"?"),0,C39/100)) -> 0.0097087379 | J39: =IF(H39=2,1,IF(AND(H39<>"",H39<>"?"),0,G39)) -> 0.0037969412 | K39: =IF(AND(H39<>"",H39<>"?"),"CONFIRMED","Market") -> Market
A41: L | B41: England | C41: =INDEX(ODDS!$D$6:$D$44,MATCH(B41,ODDS!$B$6:$B$44,0)) -> 67.647059 | D41: =INDEX(ODDS!$C$49:$C$87,MATCH(B41,ODDS!$B$49:$B$87,0)) -> 94 | E41: =C41/(C41+(SUMIF($A$41:$A$44,$A41,$C$41:$C$44)-C41)/3) -> 0.8625 | F41: =D41-C41 -> 26.352941 | G41: =E41*(D41-C41)/(0.67+0.33*E41)/100 -> 0.23809781 | H41: =POINTS!I55 | I41: =IF(H41=1,1,IF(AND(H41<>"",H41<>"?"),0,C41/100)) -> 0.67647059 | J41: =IF(H41=2,1,IF(AND(H41<>"",H41<>"?"),0,G41)) -> 0.23809781 | K41: =IF(AND(H41<>"",H41<>"?"),"CONFIRMED","Market") -> Market
A42: L | B42: Croatia | C42: =INDEX(ODDS!$D$6:$D$44,MATCH(B42,ODDS!$B$6:$B$44,0)) -> 21.568627 | D42: =INDEX(ODDS!$C$49:$C$87,MATCH(B42,ODDS!$B$49:$B$87,0)) -> 68 | E42: =C42/(C42+(SUMIF($A$41:$A$44,$A42,$C$41:$C$44)-C42)/3) -> 0.45205479 | F42: =D42-C42 -> 46.431373 | G42: =E42*(D42-C42)/(0.67+0.33*E42)/100 -> 0.25622664 | H42: =POINTS!I56 | I42: =IF(H42=1,1,IF(AND(H42<>"",H42<>"?"),0,C42/100)) -> 0.21568627 | J42: =IF(H42=2,1,IF(AND(H42<>"",H42<>"?"),0,G42)) -> 0.25622664 | K42: =IF(AND(H42<>"",H42<>"?"),"CONFIRMED","Market") -> Market
A43: L | B43: Ghana | C43: =INDEX(ODDS!$D$6:$D$44,MATCH(B43,ODDS!$B$6:$B$44,0)) -> 9.8039216 | D43: =INDEX(ODDS!$C$49:$C$87,MATCH(B43,ODDS!$B$49:$B$87,0)) -> 28 | E43: =C43/(C43+(SUMIF($A$41:$A$44,$A43,$C$41:$C$44)-C43)/3) -> 0.24590164 | F43: =D43-C43 -> 18.196078 | G43: =E43*(D43-C43)/(0.67+0.33*E43)/100 -> 0.059568131 | H43: =POINTS!I57 | I43: =IF(H43=1,1,IF(AND(H43<>"",H43<>"?"),0,C43/100)) -> 0.098039216 | J43: =IF(H43=2,1,IF(AND(H43<>"",H43<>"?"),0,G43)) -> 0.059568131 | K43: =IF(AND(H43<>"",H43<>"?"),"CONFIRMED","Market") -> Market
A44: L | B44: Panama | C44: =INDEX(ODDS!$D$6:$D$44,MATCH(B44,ODDS!$B$6:$B$44,0)) -> 0.98039216 | D44: =INDEX(ODDS!$C$49:$C$87,MATCH(B44,ODDS!$B$49:$B$87,0)) -> 10 | E44: =C44/(C44+(SUMIF($A$41:$A$44,$A44,$C$41:$C$44)-C44)/3) -> 0.028846154 | F44: =D44-C44 -> 9.0196078 | G44: =E44*(D44-C44)/(0.67+0.33*E44)/100 -> 0.0038288982 | H44: =POINTS!I58 | I44: =IF(H44=1,1,IF(AND(H44<>"",H44<>"?"),0,C44/100)) -> 0.0098039216 | J44: =IF(H44=2,1,IF(AND(H44<>"",H44<>"?"),0,G44)) -> 0.0038288982 | K44: =IF(AND(H44<>"",H44<>"?"),"CONFIRMED","Market") -> Market

Sheet M78
A1: M78 - DALLAS R32 | Jun 30
A2: 2E vs 2I
A3: WINNER: | B3: =SCHEDULE!G81 -> 0
A5: GROUP E - 2nd Place Candidates | F5: GROUP I - 2nd Place Candidates
A6: Team | B6: P(2nd) | C6: Rank | F6: Team | G6: P(2nd) | H6: Rank
A7: Germany | B7: =CALC!$J$11 -> 0.25066507 | C7: =RANK(B7,$B$7:$B$10,0) -> 2 | F7: France | G7: =CALC!$J$26 -> 0.23272701 | H7: =RANK(G7,$G$7:$G$10,0) -> 2
A8: Ecuador | B8: =CALC!$J$12 -> 0.35314349 | C8: =RANK(B8,$B$7:$B$10,0) -> 1 | F8: Senegal | G8: =CALC!$J$27 -> 0.16780302 | H8: =RANK(G8,$G$7:$G$10,0) -> 3
A9: Ivory Coast | B9: =CALC!$J$13 -> 0.21555038 | C9: =RANK(B9,$B$7:$B$10,0) -> 3 | F9: Norway | G9: =CALC!$J$28 -> 0.31197984 | H9: =RANK(G9,$G$7:$G$10,0) -> 1
A10: Curacao | B10: =CALC!$J$14 -> 0.0054322682 | C10: =RANK(B10,$B$7:$B$10,0) -> 4 | F10: TBD_I4 | G10: =CALC!$J$29 -> 0.0038613861 | H10: =RANK(G10,$G$7:$G$10,0) -> 4
A13: ALL 16 MATCHUP COMBINATIONS
A14: # | B14: Team 1 | C14: P% | D14: Team 2 | E14: P% | F14: Combined | G14: Rank
A15: 1 | B15: =$A$7 -> Germany | C15: =$B$7 -> 0.25066507 | D15: =$F$7 -> France | E15: =$G$7 -> 0.23272701 | F15: =C15*E15 -> 0.058336532 | G15: =RANK(F15,$F$15:$F$30,0) -> 6
A16: 2 | B16: =$A$7 -> Germany | C16: =$B$7 -> 0.25066507 | D16: =$F$8 -> Senegal | E16: =$G$8 -> 0.16780302 | F16: =C16*E16 -> 0.042062354 | G16: =RANK(F16,$F$15:$F$30,0) -> 8
A17: 3 | B17: =$A$7 -> Germany | C17: =$B$7 -> 0.25066507 | D17: =$F$9 -> Norway | E17: =$G$9 -> 0.31197984 | F17: =C17*E17 -> 0.078202447 | G17: =RANK(F17,$F$15:$F$30,0) -> 3
A18: 4 | B18: =$A$7 -> Germany | C18: =$B$7 -> 0.25066507 | D18: =$F$10 -> TBD_I4 | E18: =$G$10 -> 0.0038613861 | F18: =C18*E18 -> 0.00096791461 | G18: =RANK(F18,$F$15:$F$30,0) -> 13
A19: 5 | B19: =$A$8 -> Ecuador | C19: =$B$8 -> 0.35314349 | D19: =$F$7 -> France | E19: =$G$7 -> 0.23272701 | F19: =C19*E19 -> 0.082186029 | G19: =RANK(F19,$F$15:$F$30,0) -> 2
A20: 6 | B20: =$A$8 -> Ecuador | C20: =$B$8 -> 0.35314349 | D20: =$F$8 -> Senegal | E20: =$G$8 -> 0.16780302 | F20: =C20*E20 -> 0.059258543 | G20: =RANK(F20,$F$15:$F$30,0) -> 5
A21: 7 | B21: =$A$8 -> Ecuador | C21: =$B$8 -> 0.35314349 | D21: =$F$9 -> Norway | E21: =$G$9 -> 0.31197984 | F21: =C21*E21 -> 0.11017365 | G21: =RANK(F21,$F$15:$F$30,0) -> 1
A22: 8 | B22: =$A$8 -> Ecuador | C22: =$B$8 -> 0.35314349 | D22: =$F$10 -> TBD_I4 | E22: =$G$10 -> 0.0038613861 | F22: =C22*E22 -> 0.0013636234 | G22: =RANK(F22,$F$15:$F$30,0) -> 11
A23: 9 | B23: =$A$9 -> Ivory Coast | C23: =$B$9 -> 0.21555038 | D23: =$F$7 -> France | E23: =$G$7 -> 0.23272701 | F23: =C23*E23 -> 0.050164395 | G23: =RANK(F23,$F$15:$F$30,0) -> 7
A24: 10 | B24: =$A$9 -> Ivory Coast | C24: =$B$9 -> 0.21555038 | D24: =$F$8 -> Senegal | E24: =$G$8 -> 0.16780302 | F24: =C24*E24 -> 0.036170003 | G24: =RANK(F24,$F$15:$F$30,0) -> 9
A25: 11 | B25: =$A$9 -> Ivory Coast | C25: =$B$9 -> 0.21555038 | D25: =$F$9 -> Norway | E25: =$G$9 -> 0.31197984 | F25: =C25*E25 -> 0.067247372 | G25: =RANK(F25,$F$15:$F$30,0) -> 4
A26: 12 | B26: =$A$9 -> Ivory Coast | C26: =$B$9 -> 0.21555038 | D26: =$F$10 -> TBD_I4 | E26: =$G$10 -> 0.0038613861 | F26: =C26*E26 -> 0.00083232324 | G26: =RANK(F26,$F$15:$F$30,0) -> 15
A27: 13 | B27: =$A$10 -> Curacao | C27: =$B$10 -> 0.0054322682 | D27: =$F$7 -> France | E27: =$G$7 -> 0.23272701 | F27: =C27*E27 -> 0.0012642355 | G27: =RANK(F27,$F$15:$F$30,0) -> 12
A28: 14 | B28: =$A$10 -> Curacao | C28: =$B$10 -> 0.0054322682 | D28: =$F$8 -> Senegal | E28: =$G$8 -> 0.16780302 | F28: =C28*E28 -> 0.00091155098 | G28: =RANK(F28,$F$15:$F$30,0) -> 14
A29: 15 | B29: =$A$10 -> Curacao | C29: =$B$10 -> 0.0054322682 | D29: =$F$9 -> Norway | E29: =$G$9 -> 0.31197984 | F29: =C29*E29 -> 0.0016947581 | G29: =RANK(F29,$F$15:$F$30,0) -> 10
A30: 16 | B30: =$A$10 -> Curacao | C30: =$B$10 -> 0.0054322682 | D30: =$F$10 -> TBD_I4 | E30: =$G$10 -> 0.0038613861 | F30: =C30*E30 -> 2.0976085e-05 | G30: =RANK(F30,$F$15:$F$30,0) -> 16
A33: TOP 3 MOST LIKELY
A34: # | B34: Team 1 | C34: P% | D34: Team 2 | E34: P% | F34: Combined
A35: 1 | B35: =IFERROR(INDEX($B$15:$B$30,MATCH(LARGE($F$15:$F$30,1),$F$15:$F$30,0)),"-") -> Ecuador | C35: =IFERROR(INDEX($C$15:$C$30,MATCH(LARGE($F$15:$F$30,1),$F$15:$F$30,0)),0) -> 0.35314349 | D35: =IFERROR(INDEX($D$15:$D$30,MATCH(LARGE($F$15:$F$30,1),$F$15:$F$30,0)),"-") -> Norway | E35: =IFERROR(INDEX($E$15:$E$30,MATCH(LARGE($F$15:$F$30,1),$F$15:$F$30,0)),0) -> 0.31197984 | F35: =LARGE($F$15:$F$30,1) -> 0.11017365
A36: 2 | B36: =IFERROR(INDEX($B$15:$B$30,MATCH(LARGE($F$15:$F$30,2),$F$15:$F$30,0)),"-") -> Ecuador | C36: =IFERROR(INDEX($C$15:$C$30,MATCH(LARGE($F$15:$F$30,2),$F$15:$F$30,0)),0) -> 0.35314349 | D36: =IFERROR(INDEX($D$15:$D$30,MATCH(LARGE($F$15:$F$30,2),$F$15:$F$30,0)),"-") -> France | E36: =IFERROR(INDEX($E$15:$E$30,MATCH(LARGE($F$15:$F$30,2),$F$15:$F$30,0)),0) -> 0.23272701 | F36: =LARGE($F$15:$F$30,2) -> 0.082186029
A37: 3 | B37: =IFERROR(INDEX($B$15:$B$30,MATCH(LARGE($F$15:$F$30,3),$F$15:$F$30,0)),"-") -> Germany | C37: =IFERROR(INDEX($C$15:$C$30,MATCH(LARGE($F$15:$F$30,3),$F$15:$F$30,0)),0) -> 0.25066507 | D37: =IFERROR(INDEX($D$15:$D$30,MATCH(LARGE($F$15:$F$30,3),$F$15:$F$30,0)),"-") -> Norway | E37: =IFERROR(INDEX($E$15:$E$30,MATCH(LARGE($F$15:$F$30,3),$F$15:$F$30,0)),0) -> 0.31197984 | F37: =LARGE($F$15:$F$30,3) -> 0.078202447

Sheet M83
A1: M83 - Toronto R32 (feeds M93) | Jul 4
A2: 2K vs 2L
A3: WINNER: | B3: =SCHEDULE!G88 -> 0
A5: GROUP K - 2nd Place Candidates | F5: GROUP L - 2nd Place Candidates
A6: Team | B6: P(2nd) | C6: Rank | F6: Team | G6: P(2nd) | H6: Rank
A7: Portugal | B7: =CALC!$J$36 -> 0.22530289 | C7: =RANK(B7,$B$7:$B$10,0) -> 2 | F7: England | G7: =CALC!$J$41 -> 0.23809781 | H7: =RANK(G7,$G$7:$G$10,0) -> 2
A8: Colombia | B8: =CALC!$J$37 -> 0.36151026 | C8: =RANK(B8,$B$7:$B$10,0) -> 1 | F8: Croatia | G8: =CALC!$J$42 -> 0.25622664 | H8: =RANK(G8,$G$7:$G$10,0) -> 1
A9: Uzbekistan | B9: =CALC!$J$38 -> 0.022037398 | C9: =RANK(B9,$B$7:$B$10,0) -> 3 | F9: Ghana | G9: =CALC!$J$43 -> 0.059568131 | H9: =RANK(G9,$G$7:$G$10,0) -> 3
A10: TBD_K4 | B10: =CALC!$J$39 -> 0.0037969412 | C10: =RANK(B10,$B$7:$B$10,0) -> 4 | F10: Panama | G10: =CALC!$J$44 -> 0.0038288982 | H10: =RANK(G10,$G$7:$G$10,0) -> 4
A13: ALL 16 MATCHUP COMBINATIONS
A14: # | B14: Team 1 | C14: P% | D14: Team 2 | E14: P% | F14: Combined | G14: Rank
A15: 1 | B15: =$A$7 -> Portugal | C15: =$B$7 -> 0.22530289 | D15: =$F$7 -> England | E15: =$G$7 -> 0.23809781 | F15: =C15*E15 -> 0.053644123 | G15: =RANK(F15,$F$15:$F$30,0) -> 4
A16: 2 | B16: =$A$7 -> Portugal | C16: =$B$7 -> 0.22530289 | D16: =$F$8 -> Croatia | E16: =$G$8 -> 0.25622664 | F16: =C16*E16 -> 0.057728601 | G16: =RANK(F16,$F$15:$F$30,0) -> 3
A17: 3 | B17: =$A$7 -> Portugal | C17: =$B$7 -> 0.22530289 | D17: =$F$9 -> Ghana | E17: =$G$9 -> 0.059568131 | F17: =C17*E17 -> 0.013420872 | G17: =RANK(F17,$F$15:$F$30,0) -> 6
A18: 4 | B18: =$A$7 -> Portugal | C18: =$B$7 -> 0.22530289 | D18: =$F$10 -> Panama | E18: =$G$10 -> 0.0038288982 | F18: =C18*E18 -> 0.00086266181 | G18: =RANK(F18,$F$15:$F$30,0) -> 13
A19: 5 | B19: =$A$8 -> Colombia | C19: =$B$8 -> 0.36151026 | D19: =$F$7 -> England | E19: =$G$7 -> 0.23809781 | F19: =C19*E19 -> 0.086074799 | G19: =RANK(F19,$F$15:$F$30,0) -> 2
A20: 6 | B20: =$A$8 -> Colombia | C20: =$B$8 -> 0.36151026 | D20: =$F$8 -> Croatia | E20: =$G$8 -> 0.25622664 | F20: =C20*E20 -> 0.092628558 | G20: =RANK(F20,$F$15:$F$30,0) -> 1
A21: 7 | B21: =$A$8 -> Colombia | C21: =$B$8 -> 0.36151026 | D21: =$F$9 -> Ghana | E21: =$G$9 -> 0.059568131 | F21: =C21*E21 -> 0.02153449 | G21: =RANK(F21,$F$15:$F$30,0) -> 5
A22: 8 | B22: =$A$8 -> Colombia | C22: =$B$8 -> 0.36151026 | D22: =$F$10 -> Panama | E22: =$G$10 -> 0.0038288982 | F22: =C22*E22 -> 0.001384186 | G22: =RANK(F22,$F$15:$F$30,0) -> 9
A23: 9 | B23: =$A$9 -> Uzbekistan | C23: =$B$9 -> 0.022037398 | D23: =$F$7 -> England | E23: =$G$7 -> 0.23809781 | F23: =C23*E23 -> 0.0052470562 | G23: =RANK(F23,$F$15:$F$30,0) -> 8
A24: 10 | B24: =$A$9 -> Uzbekistan | C24: =$B$9 -> 0.022037398 | D24: =$F$8 -> Croatia | E24: =$G$8 -> 0.25622664 | F24: =C24*E24 -> 0.0056465685 | G24: =RANK(F24,$F$15:$F$30,0) -> 7
A25: 11 | B25: =$A$9 -> Uzbekistan | C25: =$B$9 -> 0.022037398 | D25: =$F$9 -> Ghana | E25: =$G$9 -> 0.059568131 | F25: =C25*E25 -> 0.0013127266 | G25: =RANK(F25,$F$15:$F$30,0) -> 10
A26: 12 | B26: =$A$9 -> Uzbekistan | C26: =$B$9 -> 0.022037398 | D26: =$F$10 -> Panama | E26: =$G$10 -> 0.0038288982 | F26: =C26*E26 -> 8.4378955e-05 | G26: =RANK(F26,$F$15:$F$30,0) -> 15
A27: 13 | B27: =$A$10 -> TBD_K4 | C27: =$B$10 -> 0.0037969412 | D27: =$F$7 -> England | E27: =$G$7 -> 0.23809781 | F27: =C27*E27 -> 0.00090404337 | G27: =RANK(F27,$F$15:$F$30,0) -> 12
A28: 14 | B28: =$A$10 -> TBD_K4 | C28: =$B$10 -> 0.0037969412 | D28: =$F$8 -> Croatia | E28: =$G$8 -> 0.25622664 | F28: =C28*E28 -> 0.00097287748 | G28: =RANK(F28,$F$15:$F$30,0) -> 11
A29: 15 | B29: =$A$10 -> TBD_K4 | C29: =$B$10 -> 0.0037969412 | D29: =$F$9 -> Ghana | E29: =$G$9 -> 0.059568131 | F29: =C29*E29 -> 0.00022617669 | G29: =RANK(F29,$F$15:$F$30,0) -> 14
A30: 16 | B30: =$A$10 -> TBD_K4 | C30: =$B$10 -> 0.0037969412 | D30: =$F$10 -> Panama | E30: =$G$10 -> 0.0038288982 | F30: =C30*E30 -> 1.4538101e-05 | G30: =RANK(F30,$F$15:$F$30,0) -> 16
A33: TOP 3 MOST LIKELY
A34: # | B34: Team 1 | C34: P% | D34: Team 2 | E34: P% | F34: Combined
A35: 1 | B35: =IFERROR(INDEX($B$15:$B$30,MATCH(LARGE($F$15:$F$30,1),$F$15:$F$30,0)),"-") -> Colombia | C35: =IFERROR(INDEX($C$15:$C$30,MATCH(LARGE($F$15:$F$30,1),$F$15:$F$30,0)),0) -> 0.36151026 | D35: =IFERROR(INDEX($D$15:$D$30,MATCH(LARGE($F$15:$F$30,1),$F$15:$F$30,0)),"-") -> Croatia | E35: =IFERROR(INDEX($E$15:$E$30,MATCH(LARGE($F$15:$F$30,1),$F$15:$F$30,0)),0) -> 0.25622664 | F35: =LARGE($F$15:$F$30,1) -> 0.092628558
A36: 2 | B36: =IFERROR(INDEX($B$15:$B$30,MATCH(LARGE($F$15:$F$30,2),$F$15:$F$30,0)),"-") -> Colombia | C36: =IFERROR(INDEX($C$15:$C$30,MATCH(LARGE($F$15:$F$30,2),$F$15:$F$30,0)),0) -> 0.36151026 | D36: =IFERROR(INDEX($D$15:$D$30,MATCH(LARGE($F$15:$F$30,2),$F$15:$F$30,0)),"-") -> England | E36: =IFERROR(INDEX($E$15:$E$30,MATCH(LARGE($F$15:$F$30,2),$F$15:$F$30,0)),0) -> 0.23809781 | F36: =LARGE($F$15:$F$30,2) -> 0.086074799
A37: 3 | B37: =IFERROR(INDEX($B$15:$B$30,MATCH(LARGE($F$15:$F$30,3),$F$15:$F$30,0)),"-") -> Portugal | C37: =IFERROR(INDEX($C$15:$C$30,MATCH(LARGE($F$15:$F$30,3),$F$15:$F$30,0)),0) -> 0.22530289 | D37: =IFERROR(INDEX($D$15:$D$30,MATCH(LARGE($F$15:$F$30,3),$F$15:$F$30,0)),"-") -> Croatia | E37: =IFERROR(INDEX($E$15:$E$30,MATCH(LARGE($F$15:$F$30,3),$F$15:$F$30,0)),0) -> 0.25622664 | F37: =LARGE($F$15:$F$30,3) -> 0.057728601

Sheet M84
A1: M84 - LA R32 (feeds M93) | Jul 4
A2: 1H vs 2J
A3: WINNER:
A5: GROUP H - 1st Place Candidates | F5: GROUP J - 2nd Place Candidates
A6: Team | B6: P(1st) | C6: Rank | F6: Team | G6: P(2nd) | H6: Rank
A7: Spain | B7: =CALC!$I$21 -> 0.7745098 | C7: =RANK(B7,$B$7:$B$10,0) -> 1 | F7: Argentina | G7: =CALC!$J$31 -> 0.25600729 | H7: =RANK(G7,$G$7:$G$10,0) -> 2
A8: Uruguay | B8: =CALC!$I$22 -> 0.14705882 | C8: =RANK(B8,$B$7:$B$10,0) -> 2 | F8: Austria | G8: =CALC!$J$32 -> 0.27000582 | H8: =RANK(G8,$G$7:$G$10,0) -> 1
A9: Saudi Arabia | B9: =CALC!$I$23 -> 0.039215686 | C9: =RANK(B9,$B$7:$B$10,0) -> 3 | F9: Jordan | G9: =CALC!$J$33 -> 0.048558415 | H9: =RANK(G9,$G$7:$G$10,0) -> 4
A10: Cape Verde | B10: =CALC!$I$24 -> 0.039215686 | C10: =RANK(B10,$B$7:$B$10,0) -> 3 | F10: Algeria | G10: =CALC!$J$34 -> 0.18031345 | H10: =RANK(G10,$G$7:$G$10,0) -> 3
A13: ALL 16 MATCHUP COMBINATIONS
A14: # | B14: Team 1 | C14: P% | D14: Team 2 | E14: P% | F14: Combined | G14: Rank
A15: 1 | B15: =$A$7 -> Spain | C15: =$B$7 -> 0.7745098 | D15: =$F$7 -> Argentina | E15: =$G$7 -> 0.25600729 | F15: =C15*E15 -> 0.19828016 | G15: =RANK(F15,$F$15:$F$30,0) -> 2
A16: 2 | B16: =$A$7 -> Spain | C16: =$B$7 -> 0.7745098 | D16: =$F$8 -> Austria | E16: =$G$8 -> 0.27000582 | F16: =C16*E16 -> 0.20912215 | G16: =RANK(F16,$F$15:$F$30,0) -> 1
A17: 3 | B17: =$A$7 -> Spain | C17: =$B$7 -> 0.7745098 | D17: =$F$9 -> Jordan | E17: =$G$9 -> 0.048558415 | F17: =C17*E17 -> 0.037608969 | G17: =RANK(F17,$F$15:$F$30,0) -> 6
A18: 4 | B18: =$A$7 -> Spain | C18: =$B$7 -> 0.7745098 | D18: =$F$10 -> Algeria | E18: =$G$10 -> 0.18031345 | F18: =C18*E18 -> 0.13965453 | G18: =RANK(F18,$F$15:$F$30,0) -> 3
A19: 5 | B19: =$A$8 -> Uruguay | C19: =$B$8 -> 0.14705882 | D19: =$F$7 -> Argentina | E19: =$G$7 -> 0.25600729 | F19: =C19*E19 -> 0.037648131 | G19: =RANK(F19,$F$15:$F$30,0) -> 5
A20: 6 | B20: =$A$8 -> Uruguay | C20: =$B$8 -> 0.14705882 | D20: =$F$8 -> Austria | E20: =$G$8 -> 0.27000582 | F20: =C20*E20 -> 0.039706738 | G20: =RANK(F20,$F$15:$F$30,0) -> 4
A21: 7 | B21: =$A$8 -> Uruguay | C21: =$B$8 -> 0.14705882 | D21: =$F$9 -> Jordan | E21: =$G$9 -> 0.048558415 | F21: =C21*E21 -> 0.0071409434 | G21: =RANK(F21,$F$15:$F$30,0) -> 12
A22: 8 | B22: =$A$8 -> Uruguay | C22: =$B$8 -> 0.14705882 | D22: =$F$10 -> Algeria | E22: =$G$10 -> 0.18031345 | F22: =C22*E22 -> 0.026516684 | G22: =RANK(F22,$F$15:$F$30,0) -> 7
A23: 9 | B23: =$A$9 -> Saudi Arabia | C23: =$B$9 -> 0.039215686 | D23: =$F$7 -> Argentina | E23: =$G$7 -> 0.25600729 | F23: =C23*E23 -> 0.010039502 | G23: =RANK(F23,$F$15:$F$30,0) -> 10
A24: 10 | B24: =$A$9 -> Saudi Arabia | C24: =$B$9 -> 0.039215686 | D24: =$F$8 -> Austria | E24: =$G$8 -> 0.27000582 | F24: =C24*E24 -> 0.010588463 | G24: =RANK(F24,$F$15:$F$30,0) -> 8
A25: 11 | B25: =$A$9 -> Saudi Arabia | C25: =$B$9 -> 0.039215686 | D25: =$F$9 -> Jordan | E25: =$G$9 -> 0.048558415 | F25: =C25*E25 -> 0.0019042516 | G25: =RANK(F25,$F$15:$F$30,0) -> 15
A26: 12 | B26: =$A$9 -> Saudi Arabia | C26: =$B$9 -> 0.039215686 | D26: =$F$10 -> Algeria | E26: =$G$10 -> 0.18031345 | F26: =C26*E26 -> 0.0070711156 | G26: =RANK(F26,$F$15:$F$30,0) -> 13
A27: 13 | B27: =$A$10 -> Cape Verde | C27: =$B$10 -> 0.039215686 | D27: =$F$7 -> Argentina | E27: =$G$7 -> 0.25600729 | F27: =C27*E27 -> 0.010039502 | G27: =RANK(F27,$F$15:$F$30,0) -> 10
A28: 14 | B28: =$A$10 -> Cape Verde | C28: =$B$10 -> 0.039215686 | D28: =$F$8 -> Austria | E28: =$G$8 -> 0.27000582 | F28: =C28*E28 -> 0.010588463 | G28: =RANK(F28,$F$15:$F$30,0) -> 8
A29: 15 | B29: =$A$10 -> Cape Verde | C29: =$B$10 -> 0.039215686 | D29: =$F$9 -> Jordan | E29: =$G$9 -> 0.048558415 | F29: =C29*E29 -> 0.0019042516 | G29: =RANK(F29,$F$15:$F$30,0) -> 15
A30: 16 | B30: =$A$10 -> Cape Verde | C30: =$B$10 -> 0.039215686 | D30: =$F$10 -> Algeria | E30: =$G$10 -> 0.18031345 | F30: =C30*E30 -> 0.0070711156 | G30: =RANK(F30,$F$15:$F$30,0) -> 13
A33: TOP 3 MOST LIKELY
A34: # | B34: Team 1 | C34: P% | D34: Team 2 | E34: P% | F34: Combined
A35: 1 | B35: =IFERROR(INDEX($B$15:$B$30,MATCH(LARGE($F$15:$F$30,1),$F$15:$F$30,0)),"-") -> Spain | C35: =IFERROR(INDEX($C$15:$C$30,MATCH(LARGE($F$15:$F$30,1),$F$15:$F$30,0)),0) -> 0.7745098 | D35: =IFERROR(INDEX($D$15:$D$30,MATCH(LARGE($F$15:$F$30,1),$F$15:$F$30,0)),"-") -> Austria | E35: =IFERROR(INDEX($E$15:$E$30,MATCH(LARGE($F$15:$F$30,1),$F$15:$F$30,0)),0) -> 0.27000582 | F35: =LARGE($F$15:$F$30,1) -> 0.20912215
A36: 2 | B36: =IFERROR(INDEX($B$15:$B$30,MATCH(LARGE($F$15:$F$30,2),$F$15:$F$30,0)),"-") -> Spain | C36: =IFERROR(INDEX($C$15:$C$30,MATCH(LARGE($F$15:$F$30,2),$F$15:$F$30,0)),0) -> 0.7745098 | D36: =IFERROR(INDEX($D$15:$D$30,MATCH(LARGE($F$15:$F$30,2),$F$15:$F$30,0)),"-") -> Argentina | E36: =IFERROR(INDEX($E$15:$E$30,MATCH(LARGE($F$15:$F$30,2),$F$15:$F$30,0)),0) -> 0.25600729 | F36: =LARGE($F$15:$F$30,2) -> 0.19828016
A37: 3 | B37: =IFERROR(INDEX($B$15:$B$30,MATCH(LARGE($F$15:$F$30,3),$F$15:$F$30,0)),"-") -> Spain | C37: =IFERROR(INDEX($C$15:$C$30,MATCH(LARGE($F$15:$F$30,3),$F$15:$F$30,0)),0) -> 0.7745098 | D37: =IFERROR(INDEX($D$15:$D$30,MATCH(LARGE($F$15:$F$30,3),$F$15:$F$30,0)),"-") -> Algeria | E37: =IFERROR(INDEX($E$15:$E$30,MATCH(LARGE($F$15:$F$30,3),$F$15:$F$30,0)),0) -> 0.18031345 | F37: =LARGE($F$15:$F$30,3) -> 0.13965453

Sheet M88
A1: M88 - DALLAS R32 | Jul 3
A2: 2D vs 2G
A3: WINNER:
A5: GROUP D - 2nd Place Candidates | F5: GROUP G - 2nd Place Candidates
A6: Team | B6: P(2nd) | C6: Rank | F6: Team | G6: P(2nd) | H6: Rank
A7: United States | B7: =CALC!$J$6 -> 0.29833886 | C7: =RANK(B7,$B$7:$B$10,0) -> 1 | F7: Belgium | G7: =CALC!$J$16 -> 0.23881651 | H7: =RANK(G7,$G$7:$G$10,0) -> 1
A8: Paraguay | B8: =CALC!$J$7 -> 0.22298972 | C8: =RANK(B8,$B$7:$B$10,0) -> 2 | F8: Egypt | G8: =CALC!$J$17 -> 0.19859442 | H8: =RANK(G8,$G$7:$G$10,0) -> 2
A9: Australia | B9: =CALC!$J$8 -> 0.14304352 | C9: =RANK(B9,$B$7:$B$10,0) -> 4 | F9: Iran | G9: =CALC!$J$18 -> 0.076033966 | H9: =RANK(G9,$G$7:$G$10,0) -> 3
A10: TBD_C | B10: =CALC!$J$9 -> 0.15177098 | C10: =RANK(B10,$B$7:$B$10,0) -> 3 | F10: New Zealand | G10: =CALC!$J$19 -> 0.013367841 | H10: =RANK(G10,$G$7:$G$10,0) -> 4
A13: ALL 16 MATCHUP COMBINATIONS
A14: # | B14: Team 1 | C14: P% | D14: Team 2 | E14: P% | F14: Combined | G14: Rank
